2020-06-18 06:40:02,169 - util.py[DEBUG]: Cloud-init v. 18.5-45-g3554ffe8-0ubuntu1~18.04.1 running 'init-local' at Thu, 18 Jun 2020 06:40:02 +0000. Up 8.45 seconds.
2020-06-18 06:40:02,169 - main.py[DEBUG]: No kernel command line url found.
2020-06-18 06:40:02,169 - main.py[DEBUG]: Closing stdin.
2020-06-18 06:40:02,173 - util.py[DEBUG]: Writing to /var/log/cloud-init.log - ab: [644] 0 bytes
2020-06-18 06:40:02,174 - util.py[DEBUG]: Changing the ownership of /var/log/cloud-init.log to 102:4
2020-06-18 06:40:02,174 - util.py[DEBUG]: Attempting to remove /var/lib/cloud/instance/boot-finished
2020-06-18 06:40:02,174 - util.py[DEBUG]: Attempting to remove /var/lib/cloud/data/no-net
2020-06-18 06:40:02,174 - handlers.py[DEBUG]: start: init-local/check-cache: attempting to read from cache [check]
2020-06-18 06:40:02,174 - util.py[DEBUG]: Reading from /var/lib/cloud/instance/obj.pkl (quiet=False)
2020-06-18 06:40:02,174 - stages.py[DEBUG]: no cache found
2020-06-18 06:40:02,174 - handlers.py[DEBUG]: finish: init-local/check-cache: SUCCESS: no cache found
2020-06-18 06:40:02,174 - util.py[DEBUG]: Attempting to remove /var/lib/cloud/instance
2020-06-18 06:40:02,178 - stages.py[DEBUG]: Using distro class <class 'cloudinit.distros.ubuntu.Distro'>
2020-06-18 06:40:02,178 - __init__.py[DEBUG]: Looking for data source in: ['Ec2', 'None'], via packages ['', 'cloudinit.sources'] that matches dependencies ['FILESYSTEM']
2020-06-18 06:40:02,183 - __init__.py[DEBUG]: Searching for local data source in: ['DataSourceEc2Local']
2020-06-18 06:40:02,183 - handlers.py[DEBUG]: start: init-local/search-Ec2Local: searching for local data from DataSourceEc2Local
2020-06-18 06:40:02,183 - __init__.py[DEBUG]: Seeing if we can get any data from <class 'cloudinit.sources.DataSourceEc2.DataSourceEc2Local'>
2020-06-18 06:40:02,183 - __init__.py[DEBUG]: Update datasource metadata and network config due to events: New instance first boot
2020-06-18 06:40:02,183 - util.py[DEBUG]: Reading from /sys/hypervisor/uuid (quiet=False)
2020-06-18 06:40:02,183 - util.py[DEBUG]: Read 37 bytes from /sys/hypervisor/uuid
2020-06-18 06:40:02,183 - util.py[DEBUG]: Running command ['systemd-detect-virt', '--quiet', '--container'] with allowed return codes [0] (shell=False, capture=True)
2020-06-18 06:40:02,187 - util.py[DEBUG]: Running command ['running-in-container'] with allowed return codes [0] (shell=False, capture=True)
2020-06-18 06:40:02,189 - util.py[DEBUG]: Running command ['lxc-is-container'] with allowed return codes [0] (shell=False, capture=True)
2020-06-18 06:40:02,190 - util.py[DEBUG]: Reading from /proc/1/environ (quiet=False)
2020-06-18 06:40:02,190 - util.py[DEBUG]: Read 174 bytes from /proc/1/environ
2020-06-18 06:40:02,191 - util.py[DEBUG]: Reading from /proc/self/status (quiet=False)
2020-06-18 06:40:02,191 - util.py[DEBUG]: Read 1289 bytes from /proc/self/status
2020-06-18 06:40:02,191 - util.py[DEBUG]: querying dmi data /sys/class/dmi/id/product_serial
2020-06-18 06:40:02,191 - util.py[DEBUG]: Reading from /sys/class/dmi/id/product_serial (quiet=False)
2020-06-18 06:40:02,191 - util.py[DEBUG]: Read 37 bytes from /sys/class/dmi/id/product_serial
2020-06-18 06:40:02,191 - util.py[DEBUG]: dmi data /sys/class/dmi/id/product_serial returned ec2dab58-8839-2adc-9663-85d9307c17ce
2020-06-18 06:40:02,191 - DataSourceEc2.py[DEBUG]: strict_mode: warn, cloud_name=aws cloud_platform=ec2
2020-06-18 06:40:02,199 - util.py[DEBUG]: Reading from /etc/os-release (quiet=False)
2020-06-18 06:40:02,199 - util.py[DEBUG]: Read 386 bytes from /etc/os-release
2020-06-18 06:40:02,199 - util.py[DEBUG]: Reading from /sys/class/net/eth0/name_assign_type (quiet=False)
2020-06-18 06:40:02,199 - __init__.py[DEBUG]: Found unstable nic names: ['eth0']; calling udevadm settle
2020-06-18 06:40:02,200 - util.py[DEBUG]: Running command ['udevadm', 'settle'] with allowed return codes [0] (shell=False, capture=True)
2020-06-18 06:40:02,220 - util.py[DEBUG]: Waiting for udev events to settle took 0.020 seconds
2020-06-18 06:40:02,220 - util.py[DEBUG]: Reading from /sys/class/net/eth0/carrier (quiet=False)
2020-06-18 06:40:02,220 - util.py[DEBUG]: Reading from /sys/class/net/eth0/dormant (quiet=False)
2020-06-18 06:40:02,220 - util.py[DEBUG]: Reading from /sys/class/net/eth0/operstate (quiet=False)
2020-06-18 06:40:02,220 - util.py[DEBUG]: Read 5 bytes from /sys/class/net/eth0/operstate
2020-06-18 06:40:02,220 - util.py[DEBUG]: Reading from /sys/class/net/eth0/address (quiet=False)
2020-06-18 06:40:02,220 - util.py[DEBUG]: Read 18 bytes from /sys/class/net/eth0/address
2020-06-18 06:40:02,221 - dhcp.py[DEBUG]: Performing a dhcp discovery on eth0
2020-06-18 06:40:02,221 - util.py[DEBUG]: Copying /sbin/dhclient to /var/tmp/cloud-init/cloud-init-dhcp-3greaoec/dhclient
2020-06-18 06:40:02,223 - util.py[DEBUG]: Running command ['ip', 'link', 'set', 'dev', 'eth0', 'up'] with allowed return codes [0] (shell=False, capture=True)
2020-06-18 06:40:02,230 - util.py[DEBUG]: Running command ['/var/tmp/cloud-init/cloud-init-dhcp-3greaoec/dhclient', '-1', '-v', '-lf', '/var/tmp/cloud-init/cloud-init-dhcp-3greaoec/dhcp.leases', '-pf', '/var/tmp/cloud-init/cloud-init-dhcp-3greaoec/dhclient.pid', 'eth0', '-sf', '/bin/true'] with allowed return codes [0] (shell=False, capture=True)
2020-06-18 06:40:02,263 - util.py[DEBUG]: All files appeared after 0 seconds: ['/var/tmp/cloud-init/cloud-init-dhcp-3greaoec/dhclient.pid', '/var/tmp/cloud-init/cloud-init-dhcp-3greaoec/dhcp.leases']
2020-06-18 06:40:02,264 - util.py[DEBUG]: Reading from /var/tmp/cloud-init/cloud-init-dhcp-3greaoec/dhclient.pid (quiet=False)
2020-06-18 06:40:02,264 - util.py[DEBUG]: Read 4 bytes from /var/tmp/cloud-init/cloud-init-dhcp-3greaoec/dhclient.pid
2020-06-18 06:40:02,264 - util.py[DEBUG]: Reading from /proc/547/stat (quiet=True)
2020-06-18 06:40:02,264 - util.py[DEBUG]: Read 297 bytes from /proc/547/stat
2020-06-18 06:40:02,264 - dhcp.py[DEBUG]: killing dhclient with pid=547
2020-06-18 06:40:02,265 - util.py[DEBUG]: Reading from /var/tmp/cloud-init/cloud-init-dhcp-3greaoec/dhcp.leases (quiet=False)
2020-06-18 06:40:02,265 - util.py[DEBUG]: Read 533 bytes from /var/tmp/cloud-init/cloud-init-dhcp-3greaoec/dhcp.leases
2020-06-18 06:40:02,265 - dhcp.py[DEBUG]: Received dhcp lease on eth0 for 172.31.24.65/255.255.240.0
2020-06-18 06:40:02,265 - __init__.py[DEBUG]: Attempting setup of ephemeral network on eth0 with 172.31.24.65/20 brd 172.31.31.255
2020-06-18 06:40:02,265 - util.py[DEBUG]: Running command ['ip', '-family', 'inet', 'addr', 'add', '172.31.24.65/20', 'broadcast', '172.31.31.255', 'dev', 'eth0'] with allowed return codes [0] (shell=False, capture=True)
2020-06-18 06:40:02,268 - util.py[DEBUG]: Running command ['ip', '-family', 'inet', 'link', 'set', 'dev', 'eth0', 'up'] with allowed return codes [0] (shell=False, capture=True)
2020-06-18 06:40:02,270 - util.py[DEBUG]: Running command ['ip', 'route', 'show', '0.0.0.0/0'] with allowed return codes [0] (shell=False, capture=True)
2020-06-18 06:40:02,272 - util.py[DEBUG]: Running command ['ip', '-4', 'route', 'add', '172.31.16.1', 'dev', 'eth0', 'src', '172.31.24.65'] with allowed return codes [0] (shell=False, capture=True)
2020-06-18 06:40:02,274 - util.py[DEBUG]: Running command ['ip', '-4', 'route', 'add', 'default', 'via', '172.31.16.1', 'dev', 'eth0'] with allowed return codes [0] (shell=False, capture=True)
2020-06-18 06:40:02,277 - util.py[DEBUG]: Resolving URL: http://169.254.169.254 took 0.001 seconds
2020-06-18 06:40:02,278 - util.py[DEBUG]: Resolving URL: http://instance-data.:8773 took 0.000 seconds
2020-06-18 06:40:02,278 - DataSourceEc2.py[DEBUG]: Removed the following from metadata urls: ['http://instance-data.:8773']
2020-06-18 06:40:02,278 - url_helper.py[DEBUG]: [0/1] open 'http://169.254.169.254/2009-04-04/meta-data/instance-id' with {'url': 'http://169.254.169.254/2009-04-04/meta-data/instance-id', 'allow_redirects': True, 'method': 'GET', 'timeout': 50.0, 'headers': {'User-Agent': 'Cloud-Init/18.5-45-g3554ffe8-0ubuntu1~18.04.1'}} configuration
2020-06-18 06:40:02,297 - url_helper.py[DEBUG]: Read from http://169.254.169.254/2009-04-04/meta-data/instance-id (200, 19b) after 1 attempts
2020-06-18 06:40:02,297 - DataSourceEc2.py[DEBUG]: Using metadata source: 'http://169.254.169.254'
2020-06-18 06:40:02,297 - url_helper.py[DEBUG]: [0/1] open 'http://169.254.169.254/2016-09-02/meta-data/instance-id' with {'url': 'http://169.254.169.254/2016-09-02/meta-data/instance-id', 'allow_redirects': True, 'method': 'GET', 'headers': {'User-Agent': 'Cloud-Init/18.5-45-g3554ffe8-0ubuntu1~18.04.1'}} configuration
2020-06-18 06:40:02,301 - url_helper.py[DEBUG]: Read from http://169.254.169.254/2016-09-02/meta-data/instance-id (200, 19b) after 1 attempts
2020-06-18 06:40:02,301 - DataSourceEc2.py[DEBUG]: Found preferred metadata version 2016-09-02
2020-06-18 06:40:02,301 - url_helper.py[DEBUG]: [0/6] open 'http://169.254.169.254/2016-09-02/user-data' with {'url': 'http://169.254.169.254/2016-09-02/user-data', 'allow_redirects': True, 'method': 'GET', 'timeout': 5.0, 'headers': {'User-Agent': 'Cloud-Init/18.5-45-g3554ffe8-0ubuntu1~18.04.1'}} configuration
2020-06-18 06:40:02,304 - url_helper.py[DEBUG]: Read from http://169.254.169.254/2016-09-02/user-data (200, 1481b) after 1 attempts
2020-06-18 06:40:02,304 - url_helper.py[DEBUG]: [0/6] open 'http://169.254.169.254/2016-09-02/meta-data/' with {'url': 'http://169.254.169.254/2016-09-02/meta-data/', 'allow_redirects': True, 'method': 'GET', 'timeout': 5.0, 'headers': {'User-Agent': 'Cloud-Init/18.5-45-g3554ffe8-0ubuntu1~18.04.1'}} configuration
2020-06-18 06:40:02,308 - url_helper.py[DEBUG]: Read from http://169.254.169.254/2016-09-02/meta-data/ (200, 268b) after 1 attempts
2020-06-18 06:40:02,308 - url_helper.py[DEBUG]: [0/6] open 'http://169.254.169.254/2016-09-02/meta-data/block-device-mapping/' with {'url': 'http://169.254.169.254/2016-09-02/meta-data/block-device-mapping/', 'allow_redirects': True, 'method': 'GET', 'timeout': 5.0, 'headers': {'User-Agent': 'Cloud-Init/18.5-45-g3554ffe8-0ubuntu1~18.04.1'}} configuration
2020-06-18 06:40:02,312 - url_helper.py[DEBUG]: Read from http://169.254.169.254/2016-09-02/meta-data/block-device-mapping/ (200, 30b) after 1 attempts
2020-06-18 06:40:02,312 - url_helper.py[DEBUG]: [0/6] open 'http://169.254.169.254/2016-09-02/meta-data/block-device-mapping/ami' with {'url': 'http://169.254.169.254/2016-09-02/meta-data/block-device-mapping/ami', 'allow_redirects': True, 'method': 'GET', 'timeout': 5.0, 'headers': {'User-Agent': 'Cloud-Init/18.5-45-g3554ffe8-0ubuntu1~18.04.1'}} configuration
2020-06-18 06:40:02,315 - url_helper.py[DEBUG]: Read from http://169.254.169.254/2016-09-02/meta-data/block-device-mapping/ami (200, 9b) after 1 attempts
2020-06-18 06:40:02,315 - url_helper.py[DEBUG]: [0/6] open 'http://169.254.169.254/2016-09-02/meta-data/block-device-mapping/ephemeral0' with {'url': 'http://169.254.169.254/2016-09-02/meta-data/block-device-mapping/ephemeral0', 'allow_redirects': True, 'method': 'GET', 'timeout': 5.0, 'headers': {'User-Agent': 'Cloud-Init/18.5-45-g3554ffe8-0ubuntu1~18.04.1'}} configuration
2020-06-18 06:40:02,318 - url_helper.py[DEBUG]: Read from http://169.254.169.254/2016-09-02/meta-data/block-device-mapping/ephemeral0 (200, 3b) after 1 attempts
2020-06-18 06:40:02,318 - url_helper.py[DEBUG]: [0/6] open 'http://169.254.169.254/2016-09-02/meta-data/block-device-mapping/ephemeral1' with {'url': 'http://169.254.169.254/2016-09-02/meta-data/block-device-mapping/ephemeral1', 'allow_redirects': True, 'method': 'GET', 'timeout': 5.0, 'headers': {'User-Agent': 'Cloud-Init/18.5-45-g3554ffe8-0ubuntu1~18.04.1'}} configuration
2020-06-18 06:40:02,321 - url_helper.py[DEBUG]: Read from http://169.254.169.254/2016-09-02/meta-data/block-device-mapping/ephemeral1 (200, 3b) after 1 attempts
2020-06-18 06:40:02,321 - url_helper.py[DEBUG]: [0/6] open 'http://169.254.169.254/2016-09-02/meta-data/block-device-mapping/root' with {'url': 'http://169.254.169.254/2016-09-02/meta-data/block-device-mapping/root', 'allow_redirects': True, 'method': 'GET', 'timeout': 5.0, 'headers': {'User-Agent': 'Cloud-Init/18.5-45-g3554ffe8-0ubuntu1~18.04.1'}} configuration
2020-06-18 06:40:02,324 - url_helper.py[DEBUG]: Read from http://169.254.169.254/2016-09-02/meta-data/block-device-mapping/root (200, 9b) after 1 attempts
2020-06-18 06:40:02,324 - url_helper.py[DEBUG]: [0/6] open 'http://169.254.169.254/2016-09-02/meta-data/iam/' with {'url': 'http://169.254.169.254/2016-09-02/meta-data/iam/', 'allow_redirects': True, 'method': 'GET', 'timeout': 5.0, 'headers': {'User-Agent': 'Cloud-Init/18.5-45-g3554ffe8-0ubuntu1~18.04.1'}} configuration
2020-06-18 06:40:02,327 - url_helper.py[DEBUG]: Read from http://169.254.169.254/2016-09-02/meta-data/iam/ (200, 26b) after 1 attempts
2020-06-18 06:40:02,327 - url_helper.py[DEBUG]: [0/6] open 'http://169.254.169.254/2016-09-02/meta-data/iam/info' with {'url': 'http://169.254.169.254/2016-09-02/meta-data/iam/info', 'allow_redirects': True, 'method': 'GET', 'timeout': 5.0, 'headers': {'User-Agent': 'Cloud-Init/18.5-45-g3554ffe8-0ubuntu1~18.04.1'}} configuration
2020-06-18 06:40:02,330 - url_helper.py[DEBUG]: Read from http://169.254.169.254/2016-09-02/meta-data/iam/info (200, 233b) after 1 attempts
2020-06-18 06:40:02,330 - url_helper.py[DEBUG]: [0/6] open 'http://169.254.169.254/2016-09-02/meta-data/metrics/' with {'url': 'http://169.254.169.254/2016-09-02/meta-data/metrics/', 'allow_redirects': True, 'method': 'GET', 'timeout': 5.0, 'headers': {'User-Agent': 'Cloud-Init/18.5-45-g3554ffe8-0ubuntu1~18.04.1'}} configuration
2020-06-18 06:40:02,333 - url_helper.py[DEBUG]: Read from http://169.254.169.254/2016-09-02/meta-data/metrics/ (200, 7b) after 1 attempts
2020-06-18 06:40:02,333 - url_helper.py[DEBUG]: [0/6] open 'http://169.254.169.254/2016-09-02/meta-data/metrics/vhostmd' with {'url': 'http://169.254.169.254/2016-09-02/meta-data/metrics/vhostmd', 'allow_redirects': True, 'method': 'GET', 'timeout': 5.0, 'headers': {'User-Agent': 'Cloud-Init/18.5-45-g3554ffe8-0ubuntu1~18.04.1'}} configuration
2020-06-18 06:40:02,336 - url_helper.py[DEBUG]: Read from http://169.254.169.254/2016-09-02/meta-data/metrics/vhostmd (200, 38b) after 1 attempts
2020-06-18 06:40:02,336 - url_helper.py[DEBUG]: [0/6] open 'http://169.254.169.254/2016-09-02/meta-data/network/' with {'url': 'http://169.254.169.254/2016-09-02/meta-data/network/', 'allow_redirects': True, 'method': 'GET', 'timeout': 5.0, 'headers': {'User-Agent': 'Cloud-Init/18.5-45-g3554ffe8-0ubuntu1~18.04.1'}} configuration
2020-06-18 06:40:02,340 - url_helper.py[DEBUG]: Read from http://169.254.169.254/2016-09-02/meta-data/network/ (200, 11b) after 1 attempts
2020-06-18 06:40:02,340 - url_helper.py[DEBUG]: [0/6] open 'http://169.254.169.254/2016-09-02/meta-data/network/interfaces/' with {'url': 'http://169.254.169.254/2016-09-02/meta-data/network/interfaces/', 'allow_redirects': True, 'method': 'GET', 'timeout': 5.0, 'headers': {'User-Agent': 'Cloud-Init/18.5-45-g3554ffe8-0ubuntu1~18.04.1'}} configuration
2020-06-18 06:40:02,344 - url_helper.py[DEBUG]: Read from http://169.254.169.254/2016-09-02/meta-data/network/interfaces/ (200, 5b) after 1 attempts
2020-06-18 06:40:02,344 - url_helper.py[DEBUG]: [0/6] open 'http://169.254.169.254/2016-09-02/meta-data/network/interfaces/macs/' with {'url': 'http://169.254.169.254/2016-09-02/meta-data/network/interfaces/macs/', 'allow_redirects': True, 'method': 'GET', 'timeout': 5.0, 'headers': {'User-Agent': 'Cloud-Init/18.5-45-g3554ffe8-0ubuntu1~18.04.1'}} configuration
2020-06-18 06:40:02,359 - url_helper.py[DEBUG]: Read from http://169.254.169.254/2016-09-02/meta-data/network/interfaces/macs/ (200, 18b) after 1 attempts
2020-06-18 06:40:02,360 - url_helper.py[DEBUG]: [0/6] open 'http://169.254.169.254/2016-09-02/meta-data/network/interfaces/macs/0a:36:0f:54:02:92/' with {'url': 'http://169.254.169.254/2016-09-02/meta-data/network/interfaces/macs/0a:36:0f:54:02:92/', 'allow_redirects': True, 'method': 'GET', 'timeout': 5.0, 'headers': {'User-Agent': 'Cloud-Init/18.5-45-g3554ffe8-0ubuntu1~18.04.1'}} configuration
2020-06-18 06:40:02,365 - url_helper.py[DEBUG]: Read from http://169.254.169.254/2016-09-02/meta-data/network/interfaces/macs/0a:36:0f:54:02:92/ (200, 230b) after 1 attempts
2020-06-18 06:40:02,365 - url_helper.py[DEBUG]: [0/6] open 'http://169.254.169.254/2016-09-02/meta-data/network/interfaces/macs/0a:36:0f:54:02:92/ipv4-associations/' with {'url': 'http://169.254.169.254/2016-09-02/meta-data/network/interfaces/macs/0a:36:0f:54:02:92/ipv4-associations/', 'allow_redirects': True, 'method': 'GET', 'timeout': 5.0, 'headers': {'User-Agent': 'Cloud-Init/18.5-45-g3554ffe8-0ubuntu1~18.04.1'}} configuration
2020-06-18 06:40:02,376 - url_helper.py[DEBUG]: Read from http://169.254.169.254/2016-09-02/meta-data/network/interfaces/macs/0a:36:0f:54:02:92/ipv4-associations/ (200, 13b) after 1 attempts
2020-06-18 06:40:02,376 - url_helper.py[DEBUG]: [0/6] open 'http://169.254.169.254/2016-09-02/meta-data/network/interfaces/macs/0a:36:0f:54:02:92/ipv4-associations/13.211.234.82' with {'url': 'http://169.254.169.254/2016-09-02/meta-data/network/interfaces/macs/0a:36:0f:54:02:92/ipv4-associations/13.211.234.82', 'allow_redirects': True, 'method': 'GET', 'timeout': 5.0, 'headers': {'User-Agent': 'Cloud-Init/18.5-45-g3554ffe8-0ubuntu1~18.04.1'}} configuration
2020-06-18 06:40:02,379 - url_helper.py[DEBUG]: Read from http://169.254.169.254/2016-09-02/meta-data/network/interfaces/macs/0a:36:0f:54:02:92/ipv4-associations/13.211.234.82 (200, 12b) after 1 attempts
2020-06-18 06:40:02,379 - url_helper.py[DEBUG]: [0/6] open 'http://169.254.169.254/2016-09-02/meta-data/network/interfaces/macs/0a:36:0f:54:02:92/device-number' with {'url': 'http://169.254.169.254/2016-09-02/meta-data/network/interfaces/macs/0a:36:0f:54:02:92/device-number', 'allow_redirects': True, 'method': 'GET', 'timeout': 5.0, 'headers': {'User-Agent': 'Cloud-Init/18.5-45-g3554ffe8-0ubuntu1~18.04.1'}} configuration
2020-06-18 06:40:02,389 - url_helper.py[DEBUG]: Read from http://169.254.169.254/2016-09-02/meta-data/network/interfaces/macs/0a:36:0f:54:02:92/device-number (200, 1b) after 1 attempts
2020-06-18 06:40:02,389 - url_helper.py[DEBUG]: [0/6] open 'http://169.254.169.254/2016-09-02/meta-data/network/interfaces/macs/0a:36:0f:54:02:92/interface-id' with {'url': 'http://169.254.169.254/2016-09-02/meta-data/network/interfaces/macs/0a:36:0f:54:02:92/interface-id', 'allow_redirects': True, 'method': 'GET', 'timeout': 5.0, 'headers': {'User-Agent': 'Cloud-Init/18.5-45-g3554ffe8-0ubuntu1~18.04.1'}} configuration
2020-06-18 06:40:02,392 - url_helper.py[DEBUG]: Read from http://169.254.169.254/2016-09-02/meta-data/network/interfaces/macs/0a:36:0f:54:02:92/interface-id (200, 21b) after 1 attempts
2020-06-18 06:40:02,392 - url_helper.py[DEBUG]: [0/6] open 'http://169.254.169.254/2016-09-02/meta-data/network/interfaces/macs/0a:36:0f:54:02:92/local-hostname' with {'url': 'http://169.254.169.254/2016-09-02/meta-data/network/interfaces/macs/0a:36:0f:54:02:92/local-hostname', 'allow_redirects': True, 'method': 'GET', 'timeout': 5.0, 'headers': {'User-Agent': 'Cloud-Init/18.5-45-g3554ffe8-0ubuntu1~18.04.1'}} configuration
2020-06-18 06:40:02,395 - url_helper.py[DEBUG]: Read from http://169.254.169.254/2016-09-02/meta-data/network/interfaces/macs/0a:36:0f:54:02:92/local-hostname (200, 47b) after 1 attempts
2020-06-18 06:40:02,395 - url_helper.py[DEBUG]: [0/6] open 'http://169.254.169.254/2016-09-02/meta-data/network/interfaces/macs/0a:36:0f:54:02:92/local-ipv4s' with {'url': 'http://169.254.169.254/2016-09-02/meta-data/network/interfaces/macs/0a:36:0f:54:02:92/local-ipv4s', 'allow_redirects': True, 'method': 'GET', 'timeout': 5.0, 'headers': {'User-Agent': 'Cloud-Init/18.5-45-g3554ffe8-0ubuntu1~18.04.1'}} configuration
2020-06-18 06:40:02,398 - url_helper.py[DEBUG]: Read from http://169.254.169.254/2016-09-02/meta-data/network/interfaces/macs/0a:36:0f:54:02:92/local-ipv4s (200, 12b) after 1 attempts
2020-06-18 06:40:02,398 - url_helper.py[DEBUG]: [0/6] open 'http://169.254.169.254/2016-09-02/meta-data/network/interfaces/macs/0a:36:0f:54:02:92/mac' with {'url': 'http://169.254.169.254/2016-09-02/meta-data/network/interfaces/macs/0a:36:0f:54:02:92/mac', 'allow_redirects': True, 'method': 'GET', 'timeout': 5.0, 'headers': {'User-Agent': 'Cloud-Init/18.5-45-g3554ffe8-0ubuntu1~18.04.1'}} configuration
2020-06-18 06:40:02,401 - url_helper.py[DEBUG]: Read from http://169.254.169.254/2016-09-02/meta-data/network/interfaces/macs/0a:36:0f:54:02:92/mac (200, 17b) after 1 attempts
2020-06-18 06:40:02,401 - url_helper.py[DEBUG]: [0/6] open 'http://169.254.169.254/2016-09-02/meta-data/network/interfaces/macs/0a:36:0f:54:02:92/owner-id' with {'url': 'http://169.254.169.254/2016-09-02/meta-data/network/interfaces/macs/0a:36:0f:54:02:92/owner-id', 'allow_redirects': True, 'method': 'GET', 'timeout': 5.0, 'headers': {'User-Agent': 'Cloud-Init/18.5-45-g3554ffe8-0ubuntu1~18.04.1'}} configuration
2020-06-18 06:40:02,404 - url_helper.py[DEBUG]: Read from http://169.254.169.254/2016-09-02/meta-data/network/interfaces/macs/0a:36:0f:54:02:92/owner-id (200, 12b) after 1 attempts
2020-06-18 06:40:02,404 - url_helper.py[DEBUG]: [0/6] open 'http://169.254.169.254/2016-09-02/meta-data/network/interfaces/macs/0a:36:0f:54:02:92/public-hostname' with {'url': 'http://169.254.169.254/2016-09-02/meta-data/network/interfaces/macs/0a:36:0f:54:02:92/public-hostname', 'allow_redirects': True, 'method': 'GET', 'timeout': 5.0, 'headers': {'User-Agent': 'Cloud-Init/18.5-45-g3554ffe8-0ubuntu1~18.04.1'}} configuration
2020-06-18 06:40:02,408 - url_helper.py[DEBUG]: Read from http://169.254.169.254/2016-09-02/meta-data/network/interfaces/macs/0a:36:0f:54:02:92/public-hostname (200, 54b) after 1 attempts
2020-06-18 06:40:02,408 - url_helper.py[DEBUG]: [0/6] open 'http://169.254.169.254/2016-09-02/meta-data/network/interfaces/macs/0a:36:0f:54:02:92/public-ipv4s' with {'url': 'http://169.254.169.254/2016-09-02/meta-data/network/interfaces/macs/0a:36:0f:54:02:92/public-ipv4s', 'allow_redirects': True, 'method': 'GET', 'timeout': 5.0, 'headers': {'User-Agent': 'Cloud-Init/18.5-45-g3554ffe8-0ubuntu1~18.04.1'}} configuration
2020-06-18 06:40:02,411 - url_helper.py[DEBUG]: Read from http://169.254.169.254/2016-09-02/meta-data/network/interfaces/macs/0a:36:0f:54:02:92/public-ipv4s (200, 13b) after 1 attempts
2020-06-18 06:40:02,411 - url_helper.py[DEBUG]: [0/6] open 'http://169.254.169.254/2016-09-02/meta-data/network/interfaces/macs/0a:36:0f:54:02:92/security-group-ids' with {'url': 'http://169.254.169.254/2016-09-02/meta-data/network/interfaces/macs/0a:36:0f:54:02:92/security-group-ids', 'allow_redirects': True, 'method': 'GET', 'timeout': 5.0, 'headers': {'User-Agent': 'Cloud-Init/18.5-45-g3554ffe8-0ubuntu1~18.04.1'}} configuration
2020-06-18 06:40:02,414 - url_helper.py[DEBUG]: Read from http://169.254.169.254/2016-09-02/meta-data/network/interfaces/macs/0a:36:0f:54:02:92/security-group-ids (200, 20b) after 1 attempts
2020-06-18 06:40:02,414 - url_helper.py[DEBUG]: [0/6] open 'http://169.254.169.254/2016-09-02/meta-data/network/interfaces/macs/0a:36:0f:54:02:92/security-groups' with {'url': 'http://169.254.169.254/2016-09-02/meta-data/network/interfaces/macs/0a:36:0f:54:02:92/security-groups', 'allow_redirects': True, 'method': 'GET', 'timeout': 5.0, 'headers': {'User-Agent': 'Cloud-Init/18.5-45-g3554ffe8-0ubuntu1~18.04.1'}} configuration
2020-06-18 06:40:02,417 - url_helper.py[DEBUG]: Read from http://169.254.169.254/2016-09-02/meta-data/network/interfaces/macs/0a:36:0f:54:02:92/security-groups (200, 49b) after 1 attempts
2020-06-18 06:40:02,417 - url_helper.py[DEBUG]: [0/6] open 'http://169.254.169.254/2016-09-02/meta-data/network/interfaces/macs/0a:36:0f:54:02:92/subnet-id' with {'url': 'http://169.254.169.254/2016-09-02/meta-data/network/interfaces/macs/0a:36:0f:54:02:92/subnet-id', 'allow_redirects': True, 'method': 'GET', 'timeout': 5.0, 'headers': {'User-Agent': 'Cloud-Init/18.5-45-g3554ffe8-0ubuntu1~18.04.1'}} configuration
2020-06-18 06:40:02,420 - url_helper.py[DEBUG]: Read from http://169.254.169.254/2016-09-02/meta-data/network/interfaces/macs/0a:36:0f:54:02:92/subnet-id (200, 15b) after 1 attempts
2020-06-18 06:40:02,421 - url_helper.py[DEBUG]: [0/6] open 'http://169.254.169.254/2016-09-02/meta-data/network/interfaces/macs/0a:36:0f:54:02:92/subnet-ipv4-cidr-block' with {'url': 'http://169.254.169.254/2016-09-02/meta-data/network/interfaces/macs/0a:36:0f:54:02:92/subnet-ipv4-cidr-block', 'allow_redirects': True, 'method': 'GET', 'timeout': 5.0, 'headers': {'User-Agent': 'Cloud-Init/18.5-45-g3554ffe8-0ubuntu1~18.04.1'}} configuration
2020-06-18 06:40:02,424 - url_helper.py[DEBUG]: Read from http://169.254.169.254/2016-09-02/meta-data/network/interfaces/macs/0a:36:0f:54:02:92/subnet-ipv4-cidr-block (200, 14b) after 1 attempts
2020-06-18 06:40:02,424 - url_helper.py[DEBUG]: [0/6] open 'http://169.254.169.254/2016-09-02/meta-data/network/interfaces/macs/0a:36:0f:54:02:92/vpc-id' with {'url': 'http://169.254.169.254/2016-09-02/meta-data/network/interfaces/macs/0a:36:0f:54:02:92/vpc-id', 'allow_redirects': True, 'method': 'GET', 'timeout': 5.0, 'headers': {'User-Agent': 'Cloud-Init/18.5-45-g3554ffe8-0ubuntu1~18.04.1'}} configuration
2020-06-18 06:40:02,435 - url_helper.py[DEBUG]: Read from http://169.254.169.254/2016-09-02/meta-data/network/interfaces/macs/0a:36:0f:54:02:92/vpc-id (200, 12b) after 1 attempts
2020-06-18 06:40:02,435 - url_helper.py[DEBUG]: [0/6] open 'http://169.254.169.254/2016-09-02/meta-data/network/interfaces/macs/0a:36:0f:54:02:92/vpc-ipv4-cidr-block' with {'url': 'http://169.254.169.254/2016-09-02/meta-data/network/interfaces/macs/0a:36:0f:54:02:92/vpc-ipv4-cidr-block', 'allow_redirects': True, 'method': 'GET', 'timeout': 5.0, 'headers': {'User-Agent': 'Cloud-Init/18.5-45-g3554ffe8-0ubuntu1~18.04.1'}} configuration
2020-06-18 06:40:02,439 - url_helper.py[DEBUG]: Read from http://169.254.169.254/2016-09-02/meta-data/network/interfaces/macs/0a:36:0f:54:02:92/vpc-ipv4-cidr-block (200, 13b) after 1 attempts
2020-06-18 06:40:02,439 - url_helper.py[DEBUG]: [0/6] open 'http://169.254.169.254/2016-09-02/meta-data/network/interfaces/macs/0a:36:0f:54:02:92/vpc-ipv4-cidr-blocks' with {'url': 'http://169.254.169.254/2016-09-02/meta-data/network/interfaces/macs/0a:36:0f:54:02:92/vpc-ipv4-cidr-blocks', 'allow_redirects': True, 'method': 'GET', 'timeout': 5.0, 'headers': {'User-Agent': 'Cloud-Init/18.5-45-g3554ffe8-0ubuntu1~18.04.1'}} configuration
2020-06-18 06:40:02,443 - url_helper.py[DEBUG]: Read from http://169.254.169.254/2016-09-02/meta-data/network/interfaces/macs/0a:36:0f:54:02:92/vpc-ipv4-cidr-blocks (200, 13b) after 1 attempts
2020-06-18 06:40:02,443 - url_helper.py[DEBUG]: [0/6] open 'http://169.254.169.254/2016-09-02/meta-data/placement/' with {'url': 'http://169.254.169.254/2016-09-02/meta-data/placement/', 'allow_redirects': True, 'method': 'GET', 'timeout': 5.0, 'headers': {'User-Agent': 'Cloud-Init/18.5-45-g3554ffe8-0ubuntu1~18.04.1'}} configuration
2020-06-18 06:40:02,446 - url_helper.py[DEBUG]: Read from http://169.254.169.254/2016-09-02/meta-data/placement/ (200, 17b) after 1 attempts
2020-06-18 06:40:02,446 - url_helper.py[DEBUG]: [0/6] open 'http://169.254.169.254/2016-09-02/meta-data/placement/availability-zone' with {'url': 'http://169.254.169.254/2016-09-02/meta-data/placement/availability-zone', 'allow_redirects': True, 'method': 'GET', 'timeout': 5.0, 'headers': {'User-Agent': 'Cloud-Init/18.5-45-g3554ffe8-0ubuntu1~18.04.1'}} configuration
2020-06-18 06:40:02,449 - url_helper.py[DEBUG]: Read from http://169.254.169.254/2016-09-02/meta-data/placement/availability-zone (200, 15b) after 1 attempts
2020-06-18 06:40:02,449 - url_helper.py[DEBUG]: [0/6] open 'http://169.254.169.254/2016-09-02/meta-data/public-keys/' with {'url': 'http://169.254.169.254/2016-09-02/meta-data/public-keys/', 'allow_redirects': True, 'method': 'GET', 'timeout': 5.0, 'headers': {'User-Agent': 'Cloud-Init/18.5-45-g3554ffe8-0ubuntu1~18.04.1'}} configuration
2020-06-18 06:40:02,452 - url_helper.py[DEBUG]: Read from http://169.254.169.254/2016-09-02/meta-data/public-keys/ (200, 14b) after 1 attempts
2020-06-18 06:40:02,452 - url_helper.py[DEBUG]: [0/6] open 'http://169.254.169.254/2016-09-02/meta-data/public-keys/0/openssh-key' with {'url': 'http://169.254.169.254/2016-09-02/meta-data/public-keys/0/openssh-key', 'allow_redirects': True, 'method': 'GET', 'timeout': 5.0, 'headers': {'User-Agent': 'Cloud-Init/18.5-45-g3554ffe8-0ubuntu1~18.04.1'}} configuration
2020-06-18 06:40:02,455 - url_helper.py[DEBUG]: Read from http://169.254.169.254/2016-09-02/meta-data/public-keys/0/openssh-key (200, 394b) after 1 attempts
2020-06-18 06:40:02,455 - url_helper.py[DEBUG]: [0/6] open 'http://169.254.169.254/2016-09-02/meta-data/services/' with {'url': 'http://169.254.169.254/2016-09-02/meta-data/services/', 'allow_redirects': True, 'method': 'GET', 'timeout': 5.0, 'headers': {'User-Agent': 'Cloud-Init/18.5-45-g3554ffe8-0ubuntu1~18.04.1'}} configuration
2020-06-18 06:40:02,458 - url_helper.py[DEBUG]: Read from http://169.254.169.254/2016-09-02/meta-data/services/ (200, 16b) after 1 attempts
2020-06-18 06:40:02,458 - url_helper.py[DEBUG]: [0/6] open 'http://169.254.169.254/2016-09-02/meta-data/services/domain' with {'url': 'http://169.254.169.254/2016-09-02/meta-data/services/domain', 'allow_redirects': True, 'method': 'GET', 'timeout': 5.0, 'headers': {'User-Agent': 'Cloud-Init/18.5-45-g3554ffe8-0ubuntu1~18.04.1'}} configuration
2020-06-18 06:40:02,461 - url_helper.py[DEBUG]: Read from http://169.254.169.254/2016-09-02/meta-data/services/domain (200, 13b) after 1 attempts
2020-06-18 06:40:02,461 - url_helper.py[DEBUG]: [0/6] open 'http://169.254.169.254/2016-09-02/meta-data/services/partition' with {'url': 'http://169.254.169.254/2016-09-02/meta-data/services/partition', 'allow_redirects': True, 'method': 'GET', 'timeout': 5.0, 'headers': {'User-Agent': 'Cloud-Init/18.5-45-g3554ffe8-0ubuntu1~18.04.1'}} configuration
2020-06-18 06:40:02,464 - url_helper.py[DEBUG]: Read from http://169.254.169.254/2016-09-02/meta-data/services/partition (200, 3b) after 1 attempts
2020-06-18 06:40:02,464 - url_helper.py[DEBUG]: [0/6] open 'http://169.254.169.254/2016-09-02/meta-data/ami-id' with {'url': 'http://169.254.169.254/2016-09-02/meta-data/ami-id', 'allow_redirects': True, 'method': 'GET', 'timeout': 5.0, 'headers': {'User-Agent': 'Cloud-Init/18.5-45-g3554ffe8-0ubuntu1~18.04.1'}} configuration
2020-06-18 06:40:02,467 - url_helper.py[DEBUG]: Read from http://169.254.169.254/2016-09-02/meta-data/ami-id (200, 21b) after 1 attempts
2020-06-18 06:40:02,467 - url_helper.py[DEBUG]: [0/6] open 'http://169.254.169.254/2016-09-02/meta-data/ami-launch-index' with {'url': 'http://169.254.169.254/2016-09-02/meta-data/ami-launch-index', 'allow_redirects': True, 'method': 'GET', 'timeout': 5.0, 'headers': {'User-Agent': 'Cloud-Init/18.5-45-g3554ffe8-0ubuntu1~18.04.1'}} configuration
2020-06-18 06:40:02,472 - url_helper.py[DEBUG]: Read from http://169.254.169.254/2016-09-02/meta-data/ami-launch-index (200, 1b) after 1 attempts
2020-06-18 06:40:02,473 - url_helper.py[DEBUG]: [0/6] open 'http://169.254.169.254/2016-09-02/meta-data/ami-manifest-path' with {'url': 'http://169.254.169.254/2016-09-02/meta-data/ami-manifest-path', 'allow_redirects': True, 'method': 'GET', 'timeout': 5.0, 'headers': {'User-Agent': 'Cloud-Init/18.5-45-g3554ffe8-0ubuntu1~18.04.1'}} configuration
2020-06-18 06:40:02,477 - url_helper.py[DEBUG]: Read from http://169.254.169.254/2016-09-02/meta-data/ami-manifest-path (200, 9b) after 1 attempts
2020-06-18 06:40:02,477 - url_helper.py[DEBUG]: [0/6] open 'http://169.254.169.254/2016-09-02/meta-data/hostname' with {'url': 'http://169.254.169.254/2016-09-02/meta-data/hostname', 'allow_redirects': True, 'method': 'GET', 'timeout': 5.0, 'headers': {'User-Agent': 'Cloud-Init/18.5-45-g3554ffe8-0ubuntu1~18.04.1'}} configuration
2020-06-18 06:40:02,480 - url_helper.py[DEBUG]: Read from http://169.254.169.254/2016-09-02/meta-data/hostname (200, 47b) after 1 attempts
2020-06-18 06:40:02,480 - url_helper.py[DEBUG]: [0/6] open 'http://169.254.169.254/2016-09-02/meta-data/instance-action' with {'url': 'http://169.254.169.254/2016-09-02/meta-data/instance-action', 'allow_redirects': True, 'method': 'GET', 'timeout': 5.0, 'headers': {'User-Agent': 'Cloud-Init/18.5-45-g3554ffe8-0ubuntu1~18.04.1'}} configuration
2020-06-18 06:40:02,483 - url_helper.py[DEBUG]: Read from http://169.254.169.254/2016-09-02/meta-data/instance-action (200, 4b) after 1 attempts
2020-06-18 06:40:02,483 - url_helper.py[DEBUG]: [0/6] open 'http://169.254.169.254/2016-09-02/meta-data/instance-id' with {'url': 'http://169.254.169.254/2016-09-02/meta-data/instance-id', 'allow_redirects': True, 'method': 'GET', 'timeout': 5.0, 'headers': {'User-Agent': 'Cloud-Init/18.5-45-g3554ffe8-0ubuntu1~18.04.1'}} configuration
2020-06-18 06:40:02,486 - url_helper.py[DEBUG]: Read from http://169.254.169.254/2016-09-02/meta-data/instance-id (200, 19b) after 1 attempts
2020-06-18 06:40:02,486 - url_helper.py[DEBUG]: [0/6] open 'http://169.254.169.254/2016-09-02/meta-data/instance-type' with {'url': 'http://169.254.169.254/2016-09-02/meta-data/instance-type', 'allow_redirects': True, 'method': 'GET', 'timeout': 5.0, 'headers': {'User-Agent': 'Cloud-Init/18.5-45-g3554ffe8-0ubuntu1~18.04.1'}} configuration
2020-06-18 06:40:02,488 - url_helper.py[DEBUG]: Read from http://169.254.169.254/2016-09-02/meta-data/instance-type (200, 8b) after 1 attempts
2020-06-18 06:40:02,489 - url_helper.py[DEBUG]: [0/6] open 'http://169.254.169.254/2016-09-02/meta-data/local-hostname' with {'url': 'http://169.254.169.254/2016-09-02/meta-data/local-hostname', 'allow_redirects': True, 'method': 'GET', 'timeout': 5.0, 'headers': {'User-Agent': 'Cloud-Init/18.5-45-g3554ffe8-0ubuntu1~18.04.1'}} configuration
2020-06-18 06:40:02,491 - url_helper.py[DEBUG]: Read from http://169.254.169.254/2016-09-02/meta-data/local-hostname (200, 47b) after 1 attempts
2020-06-18 06:40:02,492 - url_helper.py[DEBUG]: [0/6] open 'http://169.254.169.254/2016-09-02/meta-data/local-ipv4' with {'url': 'http://169.254.169.254/2016-09-02/meta-data/local-ipv4', 'allow_redirects': True, 'method': 'GET', 'timeout': 5.0, 'headers': {'User-Agent': 'Cloud-Init/18.5-45-g3554ffe8-0ubuntu1~18.04.1'}} configuration
2020-06-18 06:40:02,494 - url_helper.py[DEBUG]: Read from http://169.254.169.254/2016-09-02/meta-data/local-ipv4 (200, 12b) after 1 attempts
2020-06-18 06:40:02,495 - url_helper.py[DEBUG]: [0/6] open 'http://169.254.169.254/2016-09-02/meta-data/mac' with {'url': 'http://169.254.169.254/2016-09-02/meta-data/mac', 'allow_redirects': True, 'method': 'GET', 'timeout': 5.0, 'headers': {'User-Agent': 'Cloud-Init/18.5-45-g3554ffe8-0ubuntu1~18.04.1'}} configuration
2020-06-18 06:40:02,498 - url_helper.py[DEBUG]: Read from http://169.254.169.254/2016-09-02/meta-data/mac (200, 17b) after 1 attempts
2020-06-18 06:40:02,498 - url_helper.py[DEBUG]: [0/6] open 'http://169.254.169.254/2016-09-02/meta-data/profile' with {'url': 'http://169.254.169.254/2016-09-02/meta-data/profile', 'allow_redirects': True, 'method': 'GET', 'timeout': 5.0, 'headers': {'User-Agent': 'Cloud-Init/18.5-45-g3554ffe8-0ubuntu1~18.04.1'}} configuration
2020-06-18 06:40:02,501 - url_helper.py[DEBUG]: Read from http://169.254.169.254/2016-09-02/meta-data/profile (200, 11b) after 1 attempts
2020-06-18 06:40:02,501 - url_helper.py[DEBUG]: [0/6] open 'http://169.254.169.254/2016-09-02/meta-data/public-hostname' with {'url': 'http://169.254.169.254/2016-09-02/meta-data/public-hostname', 'allow_redirects': True, 'method': 'GET', 'timeout': 5.0, 'headers': {'User-Agent': 'Cloud-Init/18.5-45-g3554ffe8-0ubuntu1~18.04.1'}} configuration
2020-06-18 06:40:02,504 - url_helper.py[DEBUG]: Read from http://169.254.169.254/2016-09-02/meta-data/public-hostname (200, 54b) after 1 attempts
2020-06-18 06:40:02,505 - url_helper.py[DEBUG]: [0/6] open 'http://169.254.169.254/2016-09-02/meta-data/public-ipv4' with {'url': 'http://169.254.169.254/2016-09-02/meta-data/public-ipv4', 'allow_redirects': True, 'method': 'GET', 'timeout': 5.0, 'headers': {'User-Agent': 'Cloud-Init/18.5-45-g3554ffe8-0ubuntu1~18.04.1'}} configuration
2020-06-18 06:40:02,508 - url_helper.py[DEBUG]: Read from http://169.254.169.254/2016-09-02/meta-data/public-ipv4 (200, 13b) after 1 attempts
2020-06-18 06:40:02,508 - url_helper.py[DEBUG]: [0/6] open 'http://169.254.169.254/2016-09-02/meta-data/reservation-id' with {'url': 'http://169.254.169.254/2016-09-02/meta-data/reservation-id', 'allow_redirects': True, 'method': 'GET', 'timeout': 5.0, 'headers': {'User-Agent': 'Cloud-Init/18.5-45-g3554ffe8-0ubuntu1~18.04.1'}} configuration
2020-06-18 06:40:02,511 - url_helper.py[DEBUG]: Read from http://169.254.169.254/2016-09-02/meta-data/reservation-id (200, 19b) after 1 attempts
2020-06-18 06:40:02,511 - url_helper.py[DEBUG]: [0/6] open 'http://169.254.169.254/2016-09-02/meta-data/security-groups' with {'url': 'http://169.254.169.254/2016-09-02/meta-data/security-groups', 'allow_redirects': True, 'method': 'GET', 'timeout': 5.0, 'headers': {'User-Agent': 'Cloud-Init/18.5-45-g3554ffe8-0ubuntu1~18.04.1'}} configuration
2020-06-18 06:40:02,514 - url_helper.py[DEBUG]: Read from http://169.254.169.254/2016-09-02/meta-data/security-groups (200, 49b) after 1 attempts
2020-06-18 06:40:02,514 - url_helper.py[DEBUG]: [0/6] open 'http://169.254.169.254/2016-09-02/dynamic/instance-identity' with {'url': 'http://169.254.169.254/2016-09-02/dynamic/instance-identity', 'allow_redirects': True, 'method': 'GET', 'timeout': 5.0, 'headers': {'User-Agent': 'Cloud-Init/18.5-45-g3554ffe8-0ubuntu1~18.04.1'}} configuration
2020-06-18 06:40:02,521 - url_helper.py[DEBUG]: Read from http://169.254.169.254/2016-09-02/dynamic/instance-identity (200, 33b) after 1 attempts
2020-06-18 06:40:02,522 - url_helper.py[DEBUG]: [0/6] open 'http://169.254.169.254/2016-09-02/dynamic/instance-identity/rsa2048' with {'url': 'http://169.254.169.254/2016-09-02/dynamic/instance-identity/rsa2048', 'allow_redirects': True, 'method': 'GET', 'timeout': 5.0, 'headers': {'User-Agent': 'Cloud-Init/18.5-45-g3554ffe8-0ubuntu1~18.04.1'}} configuration
2020-06-18 06:40:02,526 - url_helper.py[DEBUG]: Read from http://169.254.169.254/2016-09-02/dynamic/instance-identity/rsa2048 (200, 1446b) after 1 attempts
2020-06-18 06:40:02,527 - url_helper.py[DEBUG]: [0/6] open 'http://169.254.169.254/2016-09-02/dynamic/instance-identity/signature' with {'url': 'http://169.254.169.254/2016-09-02/dynamic/instance-identity/signature', 'allow_redirects': True, 'method': 'GET', 'timeout': 5.0, 'headers': {'User-Agent': 'Cloud-Init/18.5-45-g3554ffe8-0ubuntu1~18.04.1'}} configuration
2020-06-18 06:40:02,529 - url_helper.py[DEBUG]: Read from http://169.254.169.254/2016-09-02/dynamic/instance-identity/signature (200, 174b) after 1 attempts
2020-06-18 06:40:02,530 - url_helper.py[DEBUG]: [0/6] open 'http://169.254.169.254/2016-09-02/dynamic/instance-identity/pkcs7' with {'url': 'http://169.254.169.254/2016-09-02/dynamic/instance-identity/pkcs7', 'allow_redirects': True, 'method': 'GET', 'timeout': 5.0, 'headers': {'User-Agent': 'Cloud-Init/18.5-45-g3554ffe8-0ubuntu1~18.04.1'}} configuration
2020-06-18 06:40:02,532 - url_helper.py[DEBUG]: Read from http://169.254.169.254/2016-09-02/dynamic/instance-identity/pkcs7 (200, 1130b) after 1 attempts
2020-06-18 06:40:02,533 - url_helper.py[DEBUG]: [0/6] open 'http://169.254.169.254/2016-09-02/dynamic/instance-identity/document' with {'url': 'http://169.254.169.254/2016-09-02/dynamic/instance-identity/document', 'allow_redirects': True, 'method': 'GET', 'timeout': 5.0, 'headers': {'User-Agent': 'Cloud-Init/18.5-45-g3554ffe8-0ubuntu1~18.04.1'}} configuration
2020-06-18 06:40:02,537 - url_helper.py[DEBUG]: Read from http://169.254.169.254/2016-09-02/dynamic/instance-identity/document (200, 486b) after 1 attempts
2020-06-18 06:40:02,537 - util.py[DEBUG]: Crawl of metadata service took 0.260 seconds
2020-06-18 06:40:02,537 - util.py[DEBUG]: Running command ['ip', '-4', 'route', 'del', 'default', 'dev', 'eth0'] with allowed return codes [0] (shell=False, capture=True)
2020-06-18 06:40:02,539 - util.py[DEBUG]: Running command ['ip', '-4', 'route', 'del', '172.31.16.1', 'dev', 'eth0', 'src', '172.31.24.65'] with allowed return codes [0] (shell=False, capture=True)
2020-06-18 06:40:02,542 - util.py[DEBUG]: Running command ['ip', '-family', 'inet', 'link', 'set', 'dev', 'eth0', 'down'] with allowed return codes [0] (shell=False, capture=True)
2020-06-18 06:40:02,544 - util.py[DEBUG]: Running command ['ip', '-family', 'inet', 'addr', 'del', '172.31.24.65/20', 'dev', 'eth0'] with allowed return codes [0] (shell=False, capture=True)
2020-06-18 06:40:02,549 - handlers.py[DEBUG]: finish: init-local/search-Ec2Local: SUCCESS: found local data from DataSourceEc2Local
2020-06-18 06:40:02,549 - stages.py[INFO]: Loaded datasource DataSourceEc2Local - DataSourceEc2Local
2020-06-18 06:40:02,549 - util.py[DEBUG]: Reading from /etc/cloud/cloud.cfg (quiet=False)
2020-06-18 06:40:02,549 - util.py[DEBUG]: Read 3594 bytes from /etc/cloud/cloud.cfg
2020-06-18 06:40:02,549 - util.py[DEBUG]: Attempting to load yaml from string of length 3594 with allowed root types (<class 'dict'>,)
2020-06-18 06:40:02,562 - util.py[DEBUG]: Reading from /etc/cloud/cloud.cfg.d/95_mirrors.cfg (quiet=False)
2020-06-18 06:40:02,562 - util.py[DEBUG]: Read 1011 bytes from /etc/cloud/cloud.cfg.d/95_mirrors.cfg
2020-06-18 06:40:02,562 - util.py[DEBUG]: Attempting to load yaml from string of length 1011 with allowed root types (<class 'dict'>,)
2020-06-18 06:40:02,566 - util.py[DEBUG]: Reading from /etc/cloud/cloud.cfg.d/90_dpkg.cfg (quiet=False)
2020-06-18 06:40:02,566 - util.py[DEBUG]: Read 257 bytes from /etc/cloud/cloud.cfg.d/90_dpkg.cfg
2020-06-18 06:40:02,566 - util.py[DEBUG]: Attempting to load yaml from string of length 257 with allowed root types (<class 'dict'>,)
2020-06-18 06:40:02,567 - util.py[DEBUG]: Reading from /etc/cloud/cloud.cfg.d/05_logging.cfg (quiet=False)
2020-06-18 06:40:02,568 - util.py[DEBUG]: Read 2057 bytes from /etc/cloud/cloud.cfg.d/05_logging.cfg
2020-06-18 06:40:02,568 - util.py[DEBUG]: Attempting to load yaml from string of length 2057 with allowed root types (<class 'dict'>,)
2020-06-18 06:40:02,571 - util.py[DEBUG]: Reading from /run/cloud-init/cloud.cfg (quiet=False)
2020-06-18 06:40:02,571 - util.py[DEBUG]: Read 31 bytes from /run/cloud-init/cloud.cfg
2020-06-18 06:40:02,571 - util.py[DEBUG]: Attempting to load yaml from string of length 31 with allowed root types (<class 'dict'>,)
2020-06-18 06:40:02,572 - util.py[DEBUG]: Attempting to load yaml from string of length 0 with allowed root types (<class 'dict'>,)
2020-06-18 06:40:02,572 - util.py[DEBUG]: loaded blob returned None, returning default.
2020-06-18 06:40:02,572 - util.py[DEBUG]: Attempting to remove /var/lib/cloud/instance
2020-06-18 06:40:02,572 - util.py[DEBUG]: Creating symbolic link from '/var/lib/cloud/instance' => '/var/lib/cloud/instances/i-0c2ccc2ca413bce53'
2020-06-18 06:40:02,573 - util.py[DEBUG]: Reading from /var/lib/cloud/instances/i-0c2ccc2ca413bce53/datasource (quiet=False)
2020-06-18 06:40:02,574 - util.py[DEBUG]: Writing to /var/lib/cloud/instances/i-0c2ccc2ca413bce53/datasource - wb: [644] 39 bytes
2020-06-18 06:40:02,574 - util.py[DEBUG]: Writing to /var/lib/cloud/data/previous-datasource - wb: [644] 39 bytes
2020-06-18 06:40:02,574 - util.py[DEBUG]: Reading from /var/lib/cloud/data/instance-id (quiet=False)
2020-06-18 06:40:02,574 - stages.py[DEBUG]: previous iid found to be NO_PREVIOUS_INSTANCE_ID
2020-06-18 06:40:02,574 - util.py[DEBUG]: Writing to /var/lib/cloud/data/instance-id - wb: [644] 20 bytes
2020-06-18 06:40:02,575 - util.py[DEBUG]: Writing to /run/cloud-init/.instance-id - wb: [644] 20 bytes
2020-06-18 06:40:02,575 - util.py[DEBUG]: Writing to /var/lib/cloud/data/previous-instance-id - wb: [644] 24 bytes
2020-06-18 06:40:02,576 - util.py[DEBUG]: Writing to /var/lib/cloud/instance/obj.pkl - wb: [400] 13802 bytes
2020-06-18 06:40:02,576 - main.py[DEBUG]: [local] init will now be targeting instance id: i-0c2ccc2ca413bce53. new=True
2020-06-18 06:40:02,576 - util.py[DEBUG]: Reading from /etc/cloud/cloud.cfg (quiet=False)
2020-06-18 06:40:02,576 - util.py[DEBUG]: Read 3594 bytes from /etc/cloud/cloud.cfg
2020-06-18 06:40:02,576 - util.py[DEBUG]: Attempting to load yaml from string of length 3594 with allowed root types (<class 'dict'>,)
2020-06-18 06:40:02,588 - util.py[DEBUG]: Reading from /etc/cloud/cloud.cfg.d/95_mirrors.cfg (quiet=False)
2020-06-18 06:40:02,589 - util.py[DEBUG]: Read 1011 bytes from /etc/cloud/cloud.cfg.d/95_mirrors.cfg
2020-06-18 06:40:02,589 - util.py[DEBUG]: Attempting to load yaml from string of length 1011 with allowed root types (<class 'dict'>,)
2020-06-18 06:40:02,592 - util.py[DEBUG]: Reading from /etc/cloud/cloud.cfg.d/90_dpkg.cfg (quiet=False)
2020-06-18 06:40:02,592 - util.py[DEBUG]: Read 257 bytes from /etc/cloud/cloud.cfg.d/90_dpkg.cfg
2020-06-18 06:40:02,592 - util.py[DEBUG]: Attempting to load yaml from string of length 257 with allowed root types (<class 'dict'>,)
2020-06-18 06:40:02,594 - util.py[DEBUG]: Reading from /etc/cloud/cloud.cfg.d/05_logging.cfg (quiet=False)
2020-06-18 06:40:02,594 - util.py[DEBUG]: Read 2057 bytes from /etc/cloud/cloud.cfg.d/05_logging.cfg
2020-06-18 06:40:02,594 - util.py[DEBUG]: Attempting to load yaml from string of length 2057 with allowed root types (<class 'dict'>,)
2020-06-18 06:40:02,597 - util.py[DEBUG]: Reading from /run/cloud-init/cloud.cfg (quiet=False)
2020-06-18 06:40:02,597 - util.py[DEBUG]: Read 31 bytes from /run/cloud-init/cloud.cfg
2020-06-18 06:40:02,597 - util.py[DEBUG]: Attempting to load yaml from string of length 31 with allowed root types (<class 'dict'>,)
2020-06-18 06:40:02,598 - util.py[DEBUG]: Attempting to load yaml from string of length 0 with allowed root types (<class 'dict'>,)
2020-06-18 06:40:02,598 - util.py[DEBUG]: loaded blob returned None, returning default.
2020-06-18 06:40:02,599 - stages.py[DEBUG]: Using distro class <class 'cloudinit.distros.ubuntu.Distro'>
2020-06-18 06:40:02,599 - cc_set_hostname.py[DEBUG]: Setting the hostname to ip-172-31-24-65.ap-southeast-2.compute.internal (ip-172-31-24-65)
2020-06-18 06:40:02,600 - util.py[DEBUG]: Reading from /etc/hostname (quiet=False)
2020-06-18 06:40:02,600 - util.py[DEBUG]: Read 7 bytes from /etc/hostname
2020-06-18 06:40:02,600 - util.py[DEBUG]: Writing to /etc/hostname - wb: [644] 16 bytes
2020-06-18 06:40:02,600 - __init__.py[DEBUG]: Non-persistently setting the system hostname to ip-172-31-24-65
2020-06-18 06:40:02,600 - util.py[DEBUG]: Running command ['hostname', 'ip-172-31-24-65'] with allowed return codes [0] (shell=False, capture=True)
2020-06-18 06:40:02,604 - util.py[DEBUG]: Reading from /sys/class/net/eth0/address (quiet=False)
2020-06-18 06:40:02,604 - util.py[DEBUG]: Read 18 bytes from /sys/class/net/eth0/address
2020-06-18 06:40:02,605 - stages.py[DEBUG]: applying net config names for {'version': 1, 'config': [{'type': 'physical', 'name': 'eth0', 'subnets': [{'type': 'dhcp4'}], 'mac_address': '0a:36:0f:54:02:92'}]}
2020-06-18 06:40:02,605 - util.py[DEBUG]: Reading from /sys/class/net/eth0/device/device (quiet=False)
2020-06-18 06:40:02,605 - util.py[DEBUG]: Reading from /sys/class/net/eth0/addr_assign_type (quiet=False)
2020-06-18 06:40:02,605 - util.py[DEBUG]: Read 2 bytes from /sys/class/net/eth0/addr_assign_type
2020-06-18 06:40:02,605 - util.py[DEBUG]: Reading from /sys/class/net/eth0/uevent (quiet=False)
2020-06-18 06:40:02,605 - util.py[DEBUG]: Read 25 bytes from /sys/class/net/eth0/uevent
2020-06-18 06:40:02,605 - util.py[DEBUG]: Reading from /sys/class/net/eth0/address (quiet=False)
2020-06-18 06:40:02,605 - util.py[DEBUG]: Read 18 bytes from /sys/class/net/eth0/address
2020-06-18 06:40:02,605 - util.py[DEBUG]: Reading from /sys/class/net/eth0/device/device (quiet=False)
2020-06-18 06:40:02,605 - util.py[DEBUG]: Reading from /sys/class/net/lo/addr_assign_type (quiet=False)
2020-06-18 06:40:02,605 - util.py[DEBUG]: Read 2 bytes from /sys/class/net/lo/addr_assign_type
2020-06-18 06:40:02,606 - util.py[DEBUG]: Reading from /sys/class/net/lo/uevent (quiet=False)
2020-06-18 06:40:02,606 - util.py[DEBUG]: Read 23 bytes from /sys/class/net/lo/uevent
2020-06-18 06:40:02,606 - util.py[DEBUG]: Reading from /sys/class/net/lo/address (quiet=False)
2020-06-18 06:40:02,606 - util.py[DEBUG]: Read 18 bytes from /sys/class/net/lo/address
2020-06-18 06:40:02,606 - util.py[DEBUG]: Reading from /sys/class/net/lo/device/device (quiet=False)
2020-06-18 06:40:02,606 - util.py[DEBUG]: Reading from /sys/class/net/eth0/operstate (quiet=False)
2020-06-18 06:40:02,606 - util.py[DEBUG]: Read 5 bytes from /sys/class/net/eth0/operstate
2020-06-18 06:40:02,606 - util.py[DEBUG]: Reading from /sys/class/net/lo/operstate (quiet=False)
2020-06-18 06:40:02,606 - util.py[DEBUG]: Read 8 bytes from /sys/class/net/lo/operstate
2020-06-18 06:40:02,606 - util.py[DEBUG]: Running command ['ip', '-6', 'addr', 'show', 'permanent', 'scope', 'global'] with allowed return codes [0] (shell=False, capture=True)
2020-06-18 06:40:02,609 - util.py[DEBUG]: Running command ['ip', '-4', 'addr', 'show'] with allowed return codes [0] (shell=False, capture=True)
2020-06-18 06:40:02,611 - __init__.py[DEBUG]: no work necessary for renaming of [['0a:36:0f:54:02:92', 'eth0', 'vif', None]]
2020-06-18 06:40:02,611 - stages.py[INFO]: Applying network configuration from ds bringup=False: {'version': 1, 'config': [{'type': 'physical', 'name': 'eth0', 'subnets': [{'type': 'dhcp4'}], 'mac_address': '0a:36:0f:54:02:92'}]}
2020-06-18 06:40:02,614 - __init__.py[DEBUG]: Selected renderer 'netplan' from priority list: None
2020-06-18 06:40:02,617 - util.py[DEBUG]: Writing to /etc/netplan/50-cloud-init.yaml - wb: [644] 473 bytes
2020-06-18 06:40:02,617 - util.py[DEBUG]: Running command ['netplan', 'generate'] with allowed return codes [0] (shell=False, capture=True)
2020-06-18 06:40:02,738 - util.py[DEBUG]: Running command ['udevadm', 'test-builtin', 'net_setup_link', '/sys/class/net/eth0'] with allowed return codes [0] (shell=False, capture=True)
2020-06-18 06:40:02,743 - util.py[DEBUG]: Running command ['udevadm', 'test-builtin', 'net_setup_link', '/sys/class/net/lo'] with allowed return codes [0] (shell=False, capture=True)
2020-06-18 06:40:02,746 - main.py[DEBUG]: [local] Exiting. datasource DataSourceEc2Local not in local mode.
2020-06-18 06:40:02,747 - util.py[DEBUG]: Reading from /proc/uptime (quiet=False)
2020-06-18 06:40:02,747 - util.py[DEBUG]: Read 10 bytes from /proc/uptime
2020-06-18 06:40:02,747 - util.py[DEBUG]: cloud-init mode 'init' took 0.615 seconds (0.62)
2020-06-18 06:40:02,747 - handlers.py[DEBUG]: finish: init-local: SUCCESS: searching for local datasources
2020-06-18 06:40:04,460 - util.py[DEBUG]: Cloud-init v. 18.5-45-g3554ffe8-0ubuntu1~18.04.1 running 'init' at Thu, 18 Jun 2020 06:40:04 +0000. Up 10.75 seconds.
2020-06-18 06:40:04,461 - main.py[DEBUG]: No kernel command line url found.
2020-06-18 06:40:04,461 - main.py[DEBUG]: Closing stdin.
2020-06-18 06:40:04,462 - util.py[DEBUG]: Writing to /var/log/cloud-init.log - ab: [644] 0 bytes
2020-06-18 06:40:04,463 - util.py[DEBUG]: Changing the ownership of /var/log/cloud-init.log to 102:4
2020-06-18 06:40:04,463 - util.py[DEBUG]: Running command ['ip', 'addr', 'show'] with allowed return codes [0] (shell=False, capture=True)
2020-06-18 06:40:04,468 - util.py[DEBUG]: Running command ['ip', '-o', 'route', 'list'] with allowed return codes [0] (shell=False, capture=True)
2020-06-18 06:40:04,470 - util.py[DEBUG]: Running command ['ip', '--oneline', '-6', 'route', 'list', 'table', 'all'] with allowed return codes [0, 1] (shell=False, capture=True)
2020-06-18 06:40:04,473 - main.py[DEBUG]: Checking to see if files that we need already exist from a previous run that would allow us to stop early.
2020-06-18 06:40:04,473 - main.py[DEBUG]: Execution continuing, no previous run detected that would allow us to stop early.
2020-06-18 06:40:04,473 - handlers.py[DEBUG]: start: init-network/check-cache: attempting to read from cache [trust]
2020-06-18 06:40:04,473 - util.py[DEBUG]: Reading from /var/lib/cloud/instance/obj.pkl (quiet=False)
2020-06-18 06:40:04,473 - util.py[DEBUG]: Read 13802 bytes from /var/lib/cloud/instance/obj.pkl
2020-06-18 06:40:04,477 - util.py[DEBUG]: Reading from /run/cloud-init/.instance-id (quiet=False)
2020-06-18 06:40:04,477 - util.py[DEBUG]: Read 20 bytes from /run/cloud-init/.instance-id
2020-06-18 06:40:04,477 - stages.py[DEBUG]: restored from cache with run check: DataSourceEc2Local
2020-06-18 06:40:04,477 - handlers.py[DEBUG]: finish: init-network/check-cache: SUCCESS: restored from cache with run check: DataSourceEc2Local
2020-06-18 06:40:04,477 - util.py[DEBUG]: Reading from /etc/cloud/cloud.cfg (quiet=False)
2020-06-18 06:40:04,477 - util.py[DEBUG]: Read 3594 bytes from /etc/cloud/cloud.cfg
2020-06-18 06:40:04,477 - util.py[DEBUG]: Attempting to load yaml from string of length 3594 with allowed root types (<class 'dict'>,)
2020-06-18 06:40:04,500 - util.py[DEBUG]: Reading from /etc/cloud/cloud.cfg.d/95_mirrors.cfg (quiet=False)
2020-06-18 06:40:04,500 - util.py[DEBUG]: Read 1011 bytes from /etc/cloud/cloud.cfg.d/95_mirrors.cfg
2020-06-18 06:40:04,500 - util.py[DEBUG]: Attempting to load yaml from string of length 1011 with allowed root types (<class 'dict'>,)
2020-06-18 06:40:04,504 - util.py[DEBUG]: Reading from /etc/cloud/cloud.cfg.d/90_dpkg.cfg (quiet=False)
2020-06-18 06:40:04,504 - util.py[DEBUG]: Read 257 bytes from /etc/cloud/cloud.cfg.d/90_dpkg.cfg
2020-06-18 06:40:04,504 - util.py[DEBUG]: Attempting to load yaml from string of length 257 with allowed root types (<class 'dict'>,)
2020-06-18 06:40:04,506 - util.py[DEBUG]: Reading from /etc/cloud/cloud.cfg.d/05_logging.cfg (quiet=False)
2020-06-18 06:40:04,506 - util.py[DEBUG]: Read 2057 bytes from /etc/cloud/cloud.cfg.d/05_logging.cfg
2020-06-18 06:40:04,506 - util.py[DEBUG]: Attempting to load yaml from string of length 2057 with allowed root types (<class 'dict'>,)
2020-06-18 06:40:04,509 - util.py[DEBUG]: Reading from /run/cloud-init/cloud.cfg (quiet=False)
2020-06-18 06:40:04,509 - util.py[DEBUG]: Read 31 bytes from /run/cloud-init/cloud.cfg
2020-06-18 06:40:04,509 - util.py[DEBUG]: Attempting to load yaml from string of length 31 with allowed root types (<class 'dict'>,)
2020-06-18 06:40:04,510 - util.py[DEBUG]: Attempting to load yaml from string of length 0 with allowed root types (<class 'dict'>,)
2020-06-18 06:40:04,510 - util.py[DEBUG]: loaded blob returned None, returning default.
2020-06-18 06:40:04,510 - util.py[DEBUG]: Attempting to remove /var/lib/cloud/instance
2020-06-18 06:40:04,511 - util.py[DEBUG]: Creating symbolic link from '/var/lib/cloud/instance' => '/var/lib/cloud/instances/i-0c2ccc2ca413bce53'
2020-06-18 06:40:04,511 - util.py[DEBUG]: Reading from /var/lib/cloud/instances/i-0c2ccc2ca413bce53/datasource (quiet=False)
2020-06-18 06:40:04,511 - util.py[DEBUG]: Read 39 bytes from /var/lib/cloud/instances/i-0c2ccc2ca413bce53/datasource
2020-06-18 06:40:04,511 - util.py[DEBUG]: Writing to /var/lib/cloud/instances/i-0c2ccc2ca413bce53/datasource - wb: [644] 39 bytes
2020-06-18 06:40:04,512 - util.py[DEBUG]: Writing to /var/lib/cloud/data/previous-datasource - wb: [644] 39 bytes
2020-06-18 06:40:04,512 - util.py[DEBUG]: Reading from /var/lib/cloud/data/instance-id (quiet=False)
2020-06-18 06:40:04,512 - util.py[DEBUG]: Read 20 bytes from /var/lib/cloud/data/instance-id
2020-06-18 06:40:04,512 - stages.py[DEBUG]: previous iid found to be i-0c2ccc2ca413bce53
2020-06-18 06:40:04,512 - util.py[DEBUG]: Writing to /var/lib/cloud/data/instance-id - wb: [644] 20 bytes
2020-06-18 06:40:04,513 - util.py[DEBUG]: Writing to /run/cloud-init/.instance-id - wb: [644] 20 bytes
2020-06-18 06:40:04,513 - util.py[DEBUG]: Writing to /var/lib/cloud/data/previous-instance-id - wb: [644] 20 bytes
2020-06-18 06:40:04,514 - util.py[DEBUG]: Writing to /var/lib/cloud/instance/obj.pkl - wb: [400] 13878 bytes
2020-06-18 06:40:04,515 - main.py[DEBUG]: [net] init will now be targeting instance id: i-0c2ccc2ca413bce53. new=False
2020-06-18 06:40:04,516 - util.py[DEBUG]: Reading from /etc/cloud/cloud.cfg (quiet=False)
2020-06-18 06:40:04,516 - util.py[DEBUG]: Read 3594 bytes from /etc/cloud/cloud.cfg
2020-06-18 06:40:04,516 - util.py[DEBUG]: Attempting to load yaml from string of length 3594 with allowed root types (<class 'dict'>,)
2020-06-18 06:40:04,528 - util.py[DEBUG]: Reading from /etc/cloud/cloud.cfg.d/95_mirrors.cfg (quiet=False)
2020-06-18 06:40:04,528 - util.py[DEBUG]: Read 1011 bytes from /etc/cloud/cloud.cfg.d/95_mirrors.cfg
2020-06-18 06:40:04,528 - util.py[DEBUG]: Attempting to load yaml from string of length 1011 with allowed root types (<class 'dict'>,)
2020-06-18 06:40:04,531 - util.py[DEBUG]: Reading from /etc/cloud/cloud.cfg.d/90_dpkg.cfg (quiet=False)
2020-06-18 06:40:04,531 - util.py[DEBUG]: Read 257 bytes from /etc/cloud/cloud.cfg.d/90_dpkg.cfg
2020-06-18 06:40:04,531 - util.py[DEBUG]: Attempting to load yaml from string of length 257 with allowed root types (<class 'dict'>,)
2020-06-18 06:40:04,533 - util.py[DEBUG]: Reading from /etc/cloud/cloud.cfg.d/05_logging.cfg (quiet=False)
2020-06-18 06:40:04,533 - util.py[DEBUG]: Read 2057 bytes from /etc/cloud/cloud.cfg.d/05_logging.cfg
2020-06-18 06:40:04,533 - util.py[DEBUG]: Attempting to load yaml from string of length 2057 with allowed root types (<class 'dict'>,)
2020-06-18 06:40:04,536 - util.py[DEBUG]: Reading from /run/cloud-init/cloud.cfg (quiet=False)
2020-06-18 06:40:04,536 - util.py[DEBUG]: Read 31 bytes from /run/cloud-init/cloud.cfg
2020-06-18 06:40:04,536 - util.py[DEBUG]: Attempting to load yaml from string of length 31 with allowed root types (<class 'dict'>,)
2020-06-18 06:40:04,537 - util.py[DEBUG]: Attempting to load yaml from string of length 0 with allowed root types (<class 'dict'>,)
2020-06-18 06:40:04,537 - util.py[DEBUG]: loaded blob returned None, returning default.
2020-06-18 06:40:04,538 - util.py[DEBUG]: Reading from /sys/class/net/eth0/address (quiet=False)
2020-06-18 06:40:04,538 - util.py[DEBUG]: Read 18 bytes from /sys/class/net/eth0/address
2020-06-18 06:40:04,538 - stages.py[DEBUG]: applying net config names for {'version': 1, 'config': [{'type': 'physical', 'name': 'eth0', 'subnets': [{'type': 'dhcp4'}], 'mac_address': '0a:36:0f:54:02:92'}]}
2020-06-18 06:40:04,539 - stages.py[DEBUG]: Using distro class <class 'cloudinit.distros.ubuntu.Distro'>
2020-06-18 06:40:04,539 - util.py[DEBUG]: Reading from /sys/class/net/eth0/device/device (quiet=False)
2020-06-18 06:40:04,539 - util.py[DEBUG]: Reading from /sys/class/net/eth0/addr_assign_type (quiet=False)
2020-06-18 06:40:04,539 - util.py[DEBUG]: Read 2 bytes from /sys/class/net/eth0/addr_assign_type
2020-06-18 06:40:04,539 - util.py[DEBUG]: Reading from /sys/class/net/eth0/uevent (quiet=False)
2020-06-18 06:40:04,539 - util.py[DEBUG]: Read 25 bytes from /sys/class/net/eth0/uevent
2020-06-18 06:40:04,540 - util.py[DEBUG]: Reading from /sys/class/net/eth0/address (quiet=False)
2020-06-18 06:40:04,540 - util.py[DEBUG]: Read 18 bytes from /sys/class/net/eth0/address
2020-06-18 06:40:04,540 - util.py[DEBUG]: Reading from /sys/class/net/eth0/device/device (quiet=False)
2020-06-18 06:40:04,540 - util.py[DEBUG]: Reading from /sys/class/net/lo/addr_assign_type (quiet=False)
2020-06-18 06:40:04,540 - util.py[DEBUG]: Read 2 bytes from /sys/class/net/lo/addr_assign_type
2020-06-18 06:40:04,540 - util.py[DEBUG]: Reading from /sys/class/net/lo/uevent (quiet=False)
2020-06-18 06:40:04,540 - util.py[DEBUG]: Read 23 bytes from /sys/class/net/lo/uevent
2020-06-18 06:40:04,540 - util.py[DEBUG]: Reading from /sys/class/net/lo/address (quiet=False)
2020-06-18 06:40:04,540 - util.py[DEBUG]: Read 18 bytes from /sys/class/net/lo/address
2020-06-18 06:40:04,540 - util.py[DEBUG]: Reading from /sys/class/net/lo/device/device (quiet=False)
2020-06-18 06:40:04,540 - util.py[DEBUG]: Reading from /sys/class/net/eth0/operstate (quiet=False)
2020-06-18 06:40:04,540 - util.py[DEBUG]: Read 3 bytes from /sys/class/net/eth0/operstate
2020-06-18 06:40:04,540 - util.py[DEBUG]: Reading from /sys/class/net/lo/operstate (quiet=False)
2020-06-18 06:40:04,540 - util.py[DEBUG]: Read 8 bytes from /sys/class/net/lo/operstate
2020-06-18 06:40:04,541 - util.py[DEBUG]: Running command ['ip', '-6', 'addr', 'show', 'permanent', 'scope', 'global'] with allowed return codes [0] (shell=False, capture=True)
2020-06-18 06:40:04,543 - util.py[DEBUG]: Running command ['ip', '-4', 'addr', 'show'] with allowed return codes [0] (shell=False, capture=True)
2020-06-18 06:40:04,545 - __init__.py[DEBUG]: no work necessary for renaming of [['0a:36:0f:54:02:92', 'eth0', 'vif', None]]
2020-06-18 06:40:04,546 - __init__.py[DEBUG]: Datasource DataSourceEc2Local not updated for events: System boot
2020-06-18 06:40:04,546 - stages.py[DEBUG]: No network config applied. Neither a new instance nor datasource network update on 'System boot' event
2020-06-18 06:40:04,546 - handlers.py[DEBUG]: start: init-network/setup-datasource: setting up datasource
2020-06-18 06:40:04,546 - handlers.py[DEBUG]: finish: init-network/setup-datasource: SUCCESS: setting up datasource
2020-06-18 06:40:04,546 - util.py[DEBUG]: Writing to /var/lib/cloud/instances/i-0c2ccc2ca413bce53/user-data.txt - wb: [600] 1481 bytes
2020-06-18 06:40:04,549 - util.py[DEBUG]: Writing to /var/lib/cloud/instances/i-0c2ccc2ca413bce53/user-data.txt.i - wb: [600] 1787 bytes
2020-06-18 06:40:04,550 - util.py[DEBUG]: Writing to /var/lib/cloud/instances/i-0c2ccc2ca413bce53/vendor-data.txt - wb: [600] 0 bytes
2020-06-18 06:40:04,551 - util.py[DEBUG]: Writing to /var/lib/cloud/instances/i-0c2ccc2ca413bce53/vendor-data.txt.i - wb: [600] 308 bytes
2020-06-18 06:40:04,552 - util.py[DEBUG]: Reading from /var/lib/cloud/data/set-hostname (quiet=False)
2020-06-18 06:40:04,552 - util.py[DEBUG]: Read 95 bytes from /var/lib/cloud/data/set-hostname
2020-06-18 06:40:04,552 - cc_set_hostname.py[DEBUG]: No hostname changes. Skipping set-hostname
2020-06-18 06:40:04,552 - util.py[DEBUG]: Writing to /var/lib/cloud/instances/i-0c2ccc2ca413bce53/sem/consume_data - wb: [644] 24 bytes
2020-06-18 06:40:04,553 - helpers.py[DEBUG]: Running consume_data using lock (<FileLock using file '/var/lib/cloud/instances/i-0c2ccc2ca413bce53/sem/consume_data'>)
2020-06-18 06:40:04,553 - handlers.py[DEBUG]: start: init-network/consume-user-data: reading and applying user-data
2020-06-18 06:40:04,553 - launch_index.py[DEBUG]: Discarding 0 multipart messages which do not match launch index 0
2020-06-18 06:40:04,553 - stages.py[DEBUG]: Added default handler for {'text/cloud-config-jsonp', 'text/cloud-config'} from CloudConfigPartHandler: [['text/cloud-config', 'text/cloud-config-jsonp']]
2020-06-18 06:40:04,553 - stages.py[DEBUG]: Added default handler for {'text/x-shellscript'} from ShellScriptPartHandler: [['text/x-shellscript']]
2020-06-18 06:40:04,553 - stages.py[DEBUG]: Added default handler for {'text/cloud-boothook'} from BootHookPartHandler: [['text/cloud-boothook']]
2020-06-18 06:40:04,553 - stages.py[DEBUG]: Added default handler for {'text/upstart-job'} from UpstartJobPartHandler: [['text/upstart-job']]
2020-06-18 06:40:04,553 - stages.py[DEBUG]: Added default handler for {'text/jinja2'} from JinjaTemplatePartHandler: [['text/jinja2']]
2020-06-18 06:40:04,554 - __init__.py[DEBUG]: Calling handler CloudConfigPartHandler: [['text/cloud-config', 'text/cloud-config-jsonp']] (__begin__, None, 3) with frequency once-per-instance
2020-06-18 06:40:04,554 - __init__.py[DEBUG]: Calling handler ShellScriptPartHandler: [['text/x-shellscript']] (__begin__, None, 2) with frequency once-per-instance
2020-06-18 06:40:04,554 - __init__.py[DEBUG]: Calling handler BootHookPartHandler: [['text/cloud-boothook']] (__begin__, None, 2) with frequency once-per-instance
2020-06-18 06:40:04,554 - __init__.py[DEBUG]: Calling handler UpstartJobPartHandler: [['text/upstart-job']] (__begin__, None, 2) with frequency once-per-instance
2020-06-18 06:40:04,554 - __init__.py[DEBUG]: Calling handler JinjaTemplatePartHandler: [['text/jinja2']] (__begin__, None, 3) with frequency once-per-instance
2020-06-18 06:40:04,554 - __init__.py[DEBUG]: {'MIME-Version': '1.0', 'Content-Type': 'text/x-shellscript', 'Content-Disposition': 'attachment; filename="part-001"'}
2020-06-18 06:40:04,554 - __init__.py[DEBUG]: Calling handler ShellScriptPartHandler: [['text/x-shellscript']] (text/x-shellscript, part-001, 2) with frequency once-per-instance
2020-06-18 06:40:04,554 - util.py[DEBUG]: Writing to /var/lib/cloud/instance/scripts/part-001 - wb: [700] 1481 bytes
2020-06-18 06:40:04,555 - __init__.py[DEBUG]: Calling handler CloudConfigPartHandler: [['text/cloud-config', 'text/cloud-config-jsonp']] (__end__, None, 3) with frequency once-per-instance
2020-06-18 06:40:04,555 - util.py[DEBUG]: Writing to /var/lib/cloud/instances/i-0c2ccc2ca413bce53/cloud-config.txt - wb: [600] 0 bytes
2020-06-18 06:40:04,555 - __init__.py[DEBUG]: Calling handler ShellScriptPartHandler: [['text/x-shellscript']] (__end__, None, 2) with frequency once-per-instance
2020-06-18 06:40:04,555 - __init__.py[DEBUG]: Calling handler BootHookPartHandler: [['text/cloud-boothook']] (__end__, None, 2) with frequency once-per-instance
2020-06-18 06:40:04,555 - __init__.py[DEBUG]: Calling handler UpstartJobPartHandler: [['text/upstart-job']] (__end__, None, 2) with frequency once-per-instance
2020-06-18 06:40:04,555 - __init__.py[DEBUG]: Calling handler JinjaTemplatePartHandler: [['text/jinja2']] (__end__, None, 3) with frequency once-per-instance
2020-06-18 06:40:04,555 - handlers.py[DEBUG]: finish: init-network/consume-user-data: SUCCESS: reading and applying user-data
2020-06-18 06:40:04,555 - handlers.py[DEBUG]: start: init-network/consume-vendor-data: reading and applying vendor-data
2020-06-18 06:40:04,555 - stages.py[DEBUG]: no vendordata from datasource
2020-06-18 06:40:04,556 - handlers.py[DEBUG]: finish: init-network/consume-vendor-data: SUCCESS: reading and applying vendor-data
2020-06-18 06:40:04,556 - util.py[DEBUG]: Reading from /etc/cloud/cloud.cfg (quiet=False)
2020-06-18 06:40:04,556 - util.py[DEBUG]: Read 3594 bytes from /etc/cloud/cloud.cfg
2020-06-18 06:40:04,556 - util.py[DEBUG]: Attempting to load yaml from string of length 3594 with allowed root types (<class 'dict'>,)
2020-06-18 06:40:04,568 - util.py[DEBUG]: Reading from /etc/cloud/cloud.cfg.d/95_mirrors.cfg (quiet=False)
2020-06-18 06:40:04,568 - util.py[DEBUG]: Read 1011 bytes from /etc/cloud/cloud.cfg.d/95_mirrors.cfg
2020-06-18 06:40:04,568 - util.py[DEBUG]: Attempting to load yaml from string of length 1011 with allowed root types (<class 'dict'>,)
2020-06-18 06:40:04,571 - util.py[DEBUG]: Reading from /etc/cloud/cloud.cfg.d/90_dpkg.cfg (quiet=False)
2020-06-18 06:40:04,572 - util.py[DEBUG]: Read 257 bytes from /etc/cloud/cloud.cfg.d/90_dpkg.cfg
2020-06-18 06:40:04,572 - util.py[DEBUG]: Attempting to load yaml from string of length 257 with allowed root types (<class 'dict'>,)
2020-06-18 06:40:04,573 - util.py[DEBUG]: Reading from /etc/cloud/cloud.cfg.d/05_logging.cfg (quiet=False)
2020-06-18 06:40:04,573 - util.py[DEBUG]: Read 2057 bytes from /etc/cloud/cloud.cfg.d/05_logging.cfg
2020-06-18 06:40:04,573 - util.py[DEBUG]: Attempting to load yaml from string of length 2057 with allowed root types (<class 'dict'>,)
2020-06-18 06:40:04,577 - util.py[DEBUG]: Reading from /run/cloud-init/cloud.cfg (quiet=False)
2020-06-18 06:40:04,577 - util.py[DEBUG]: Read 31 bytes from /run/cloud-init/cloud.cfg
2020-06-18 06:40:04,577 - util.py[DEBUG]: Attempting to load yaml from string of length 31 with allowed root types (<class 'dict'>,)
2020-06-18 06:40:04,577 - util.py[DEBUG]: Attempting to load yaml from string of length 0 with allowed root types (<class 'dict'>,)
2020-06-18 06:40:04,577 - util.py[DEBUG]: loaded blob returned None, returning default.
2020-06-18 06:40:04,578 - util.py[DEBUG]: Reading from /var/lib/cloud/instance/cloud-config.txt (quiet=False)
2020-06-18 06:40:04,578 - util.py[DEBUG]: Read 0 bytes from /var/lib/cloud/instance/cloud-config.txt
2020-06-18 06:40:04,578 - util.py[DEBUG]: Attempting to load yaml from string of length 0 with allowed root types (<class 'dict'>,)
2020-06-18 06:40:04,578 - util.py[DEBUG]: loaded blob returned None, returning default.
2020-06-18 06:40:04,578 - util.py[DEBUG]: Reading from /var/lib/cloud/instance/cloud-config.txt (quiet=False)
2020-06-18 06:40:04,579 - util.py[DEBUG]: Read 0 bytes from /var/lib/cloud/instance/cloud-config.txt
2020-06-18 06:40:04,579 - util.py[DEBUG]: Attempting to load yaml from string of length 0 with allowed root types (<class 'dict'>,)
2020-06-18 06:40:04,579 - util.py[DEBUG]: loaded blob returned None, returning default.
2020-06-18 06:40:04,590 - handlers.py[DEBUG]: start: init-network/activate-datasource: activating datasource
2020-06-18 06:40:04,590 - util.py[DEBUG]: Writing to /var/lib/cloud/instance/obj.pkl - wb: [400] 17705 bytes
2020-06-18 06:40:04,591 - handlers.py[DEBUG]: finish: init-network/activate-datasource: SUCCESS: activating datasource
2020-06-18 06:40:04,591 - main.py[DEBUG]: no di_report found in config.
2020-06-18 06:40:04,641 - stages.py[DEBUG]: Using distro class <class 'cloudinit.distros.ubuntu.Distro'>
2020-06-18 06:40:04,642 - stages.py[DEBUG]: Running module migrator (<module 'cloudinit.config.cc_migrator' from '/usr/lib/python3/dist-packages/cloudinit/config/cc_migrator.py'>) with frequency always
2020-06-18 06:40:04,642 - handlers.py[DEBUG]: start: init-network/config-migrator: running config-migrator with frequency always
2020-06-18 06:40:04,642 - helpers.py[DEBUG]: Running config-migrator using lock (<cloudinit.helpers.DummyLock object at 0x7fdd01637fd0>)
2020-06-18 06:40:04,642 - cc_migrator.py[DEBUG]: Migrated 0 semaphore files to there canonicalized names
2020-06-18 06:40:04,642 - handlers.py[DEBUG]: finish: init-network/config-migrator: SUCCESS: config-migrator ran successfully
2020-06-18 06:40:04,642 - stages.py[DEBUG]: Running module seed_random (<module 'cloudinit.config.cc_seed_random' from '/usr/lib/python3/dist-packages/cloudinit/config/cc_seed_random.py'>) with frequency once-per-instance
2020-06-18 06:40:04,643 - handlers.py[DEBUG]: start: init-network/config-seed_random: running config-seed_random with frequency once-per-instance
2020-06-18 06:40:04,643 - util.py[DEBUG]: Writing to /var/lib/cloud/instances/i-0c2ccc2ca413bce53/sem/config_seed_random - wb: [644] 23 bytes
2020-06-18 06:40:04,643 - helpers.py[DEBUG]: Running config-seed_random using lock (<FileLock using file '/var/lib/cloud/instances/i-0c2ccc2ca413bce53/sem/config_seed_random'>)
2020-06-18 06:40:04,643 - cc_seed_random.py[DEBUG]: no command provided
2020-06-18 06:40:04,643 - handlers.py[DEBUG]: finish: init-network/config-seed_random: SUCCESS: config-seed_random ran successfully
2020-06-18 06:40:04,643 - stages.py[DEBUG]: Running module bootcmd (<module 'cloudinit.config.cc_bootcmd' from '/usr/lib/python3/dist-packages/cloudinit/config/cc_bootcmd.py'>) with frequency always
2020-06-18 06:40:04,644 - handlers.py[DEBUG]: start: init-network/config-bootcmd: running config-bootcmd with frequency always
2020-06-18 06:40:04,644 - helpers.py[DEBUG]: Running config-bootcmd using lock (<cloudinit.helpers.DummyLock object at 0x7fdcfe71f358>)
2020-06-18 06:40:04,644 - cc_bootcmd.py[DEBUG]: Skipping module named bootcmd, no 'bootcmd' key in configuration
2020-06-18 06:40:04,644 - handlers.py[DEBUG]: finish: init-network/config-bootcmd: SUCCESS: config-bootcmd ran successfully
2020-06-18 06:40:04,644 - stages.py[DEBUG]: Running module write-files (<module 'cloudinit.config.cc_write_files' from '/usr/lib/python3/dist-packages/cloudinit/config/cc_write_files.py'>) with frequency once-per-instance
2020-06-18 06:40:04,644 - handlers.py[DEBUG]: start: init-network/config-write-files: running config-write-files with frequency once-per-instance
2020-06-18 06:40:04,644 - util.py[DEBUG]: Writing to /var/lib/cloud/instances/i-0c2ccc2ca413bce53/sem/config_write_files - wb: [644] 24 bytes
2020-06-18 06:40:04,644 - helpers.py[DEBUG]: Running config-write-files using lock (<FileLock using file '/var/lib/cloud/instances/i-0c2ccc2ca413bce53/sem/config_write_files'>)
2020-06-18 06:40:04,645 - cc_write_files.py[DEBUG]: Skipping module named write-files, no/empty 'write_files' key in configuration
2020-06-18 06:40:04,645 - handlers.py[DEBUG]: finish: init-network/config-write-files: SUCCESS: config-write-files ran successfully
2020-06-18 06:40:04,645 - stages.py[DEBUG]: Running module growpart (<module 'cloudinit.config.cc_growpart' from '/usr/lib/python3/dist-packages/cloudinit/config/cc_growpart.py'>) with frequency always
2020-06-18 06:40:04,645 - handlers.py[DEBUG]: start: init-network/config-growpart: running config-growpart with frequency always
2020-06-18 06:40:04,645 - helpers.py[DEBUG]: Running config-growpart using lock (<cloudinit.helpers.DummyLock object at 0x7fdcfe71f710>)
2020-06-18 06:40:04,645 - cc_growpart.py[DEBUG]: No 'growpart' entry in cfg.  Using default: {'mode': 'auto', 'devices': ['/'], 'ignore_growroot_disabled': False}
2020-06-18 06:40:04,645 - util.py[DEBUG]: Running command ['growpart', '--help'] with allowed return codes [0] (shell=False, capture=True)
2020-06-18 06:40:04,654 - util.py[DEBUG]: Reading from /proc/619/mountinfo (quiet=False)
2020-06-18 06:40:04,655 - util.py[DEBUG]: Read 2886 bytes from /proc/619/mountinfo
2020-06-18 06:40:04,655 - util.py[DEBUG]: Running command ['systemd-detect-virt', '--quiet', '--container'] with allowed return codes [0] (shell=False, capture=True)
2020-06-18 06:40:04,667 - util.py[DEBUG]: Running command ['running-in-container'] with allowed return codes [0] (shell=False, capture=True)
2020-06-18 06:40:04,670 - util.py[DEBUG]: Running command ['lxc-is-container'] with allowed return codes [0] (shell=False, capture=True)
2020-06-18 06:40:04,671 - util.py[DEBUG]: Reading from /proc/1/environ (quiet=False)
2020-06-18 06:40:04,671 - util.py[DEBUG]: Read 174 bytes from /proc/1/environ
2020-06-18 06:40:04,671 - util.py[DEBUG]: Reading from /proc/self/status (quiet=False)
2020-06-18 06:40:04,672 - util.py[DEBUG]: Read 1289 bytes from /proc/self/status
2020-06-18 06:40:04,673 - util.py[DEBUG]: Reading from /etc/os-release (quiet=False)
2020-06-18 06:40:04,673 - util.py[DEBUG]: Read 386 bytes from /etc/os-release
2020-06-18 06:40:04,673 - util.py[DEBUG]: Reading from /sys/class/block/xvda1/partition (quiet=False)
2020-06-18 06:40:04,673 - util.py[DEBUG]: Read 2 bytes from /sys/class/block/xvda1/partition
2020-06-18 06:40:04,674 - util.py[DEBUG]: Reading from /sys/devices/vbd-768/block/xvda/dev (quiet=False)
2020-06-18 06:40:04,674 - util.py[DEBUG]: Read 6 bytes from /sys/devices/vbd-768/block/xvda/dev
2020-06-18 06:40:04,679 - util.py[DEBUG]: Running command ['growpart', '--dry-run', '/dev/xvda', '1'] with allowed return codes [0] (shell=False, capture=True)
2020-06-18 06:40:04,807 - util.py[DEBUG]: resize_devices took 0.153 seconds
2020-06-18 06:40:04,807 - cc_growpart.py[DEBUG]: '/' NOCHANGE: no change necessary (/dev/xvda, 1)
2020-06-18 06:40:04,807 - handlers.py[DEBUG]: finish: init-network/config-growpart: SUCCESS: config-growpart ran successfully
2020-06-18 06:40:04,808 - stages.py[DEBUG]: Running module resizefs (<module 'cloudinit.config.cc_resizefs' from '/usr/lib/python3/dist-packages/cloudinit/config/cc_resizefs.py'>) with frequency always
2020-06-18 06:40:04,808 - handlers.py[DEBUG]: start: init-network/config-resizefs: running config-resizefs with frequency always
2020-06-18 06:40:04,808 - helpers.py[DEBUG]: Running config-resizefs using lock (<cloudinit.helpers.DummyLock object at 0x7fdcfe752898>)
2020-06-18 06:40:04,850 - util.py[DEBUG]: Reading from /proc/619/mountinfo (quiet=False)
2020-06-18 06:40:04,850 - util.py[DEBUG]: Read 2886 bytes from /proc/619/mountinfo
2020-06-18 06:40:04,850 - cc_resizefs.py[DEBUG]: resize_info: dev=/dev/xvda1 mnt_point=/ path=/
2020-06-18 06:40:04,850 - util.py[DEBUG]: Running command ['systemd-detect-virt', '--quiet', '--container'] with allowed return codes [0] (shell=False, capture=True)
2020-06-18 06:40:04,859 - util.py[DEBUG]: Running command ['running-in-container'] with allowed return codes [0] (shell=False, capture=True)
2020-06-18 06:40:04,861 - util.py[DEBUG]: Running command ['lxc-is-container'] with allowed return codes [0] (shell=False, capture=True)
2020-06-18 06:40:04,862 - util.py[DEBUG]: Reading from /proc/1/environ (quiet=False)
2020-06-18 06:40:04,863 - util.py[DEBUG]: Read 174 bytes from /proc/1/environ
2020-06-18 06:40:04,863 - util.py[DEBUG]: Reading from /proc/self/status (quiet=False)
2020-06-18 06:40:04,863 - util.py[DEBUG]: Read 1289 bytes from /proc/self/status
2020-06-18 06:40:04,864 - cc_resizefs.py[DEBUG]: Resizing / (ext4) using resize2fs /dev/xvda1
2020-06-18 06:40:04,864 - util.py[DEBUG]: Running command ('resize2fs', '/dev/xvda1') with allowed return codes [0] (shell=False, capture=True)
2020-06-18 06:40:04,880 - util.py[DEBUG]: Resizing took 0.016 seconds
2020-06-18 06:40:04,880 - cc_resizefs.py[DEBUG]: Resized root filesystem (type=ext4, val=True)
2020-06-18 06:40:04,881 - handlers.py[DEBUG]: finish: init-network/config-resizefs: SUCCESS: config-resizefs ran successfully
2020-06-18 06:40:04,881 - stages.py[DEBUG]: Running module disk_setup (<module 'cloudinit.config.cc_disk_setup' from '/usr/lib/python3/dist-packages/cloudinit/config/cc_disk_setup.py'>) with frequency once-per-instance
2020-06-18 06:40:04,881 - handlers.py[DEBUG]: start: init-network/config-disk_setup: running config-disk_setup with frequency once-per-instance
2020-06-18 06:40:04,881 - util.py[DEBUG]: Writing to /var/lib/cloud/instances/i-0c2ccc2ca413bce53/sem/config_disk_setup - wb: [644] 24 bytes
2020-06-18 06:40:04,882 - helpers.py[DEBUG]: Running config-disk_setup using lock (<FileLock using file '/var/lib/cloud/instances/i-0c2ccc2ca413bce53/sem/config_disk_setup'>)
2020-06-18 06:40:04,882 - handlers.py[DEBUG]: finish: init-network/config-disk_setup: SUCCESS: config-disk_setup ran successfully
2020-06-18 06:40:04,882 - stages.py[DEBUG]: Running module mounts (<module 'cloudinit.config.cc_mounts' from '/usr/lib/python3/dist-packages/cloudinit/config/cc_mounts.py'>) with frequency once-per-instance
2020-06-18 06:40:04,882 - handlers.py[DEBUG]: start: init-network/config-mounts: running config-mounts with frequency once-per-instance
2020-06-18 06:40:04,882 - util.py[DEBUG]: Writing to /var/lib/cloud/instances/i-0c2ccc2ca413bce53/sem/config_mounts - wb: [644] 24 bytes
2020-06-18 06:40:04,883 - helpers.py[DEBUG]: Running config-mounts using lock (<FileLock using file '/var/lib/cloud/instances/i-0c2ccc2ca413bce53/sem/config_mounts'>)
2020-06-18 06:40:04,883 - cc_mounts.py[DEBUG]: mounts configuration is []
2020-06-18 06:40:04,883 - util.py[DEBUG]: Reading from /etc/fstab (quiet=False)
2020-06-18 06:40:04,883 - util.py[DEBUG]: Read 51 bytes from /etc/fstab
2020-06-18 06:40:04,886 - cc_mounts.py[DEBUG]: Attempting to determine the real name of ephemeral0
2020-06-18 06:40:04,887 - cc_mounts.py[DEBUG]: changed default device ephemeral0 => None
2020-06-18 06:40:04,887 - cc_mounts.py[DEBUG]: Ignoring nonexistent default named mount ephemeral0
2020-06-18 06:40:04,887 - cc_mounts.py[DEBUG]: Attempting to determine the real name of swap
2020-06-18 06:40:04,887 - DataSourceEc2.py[DEBUG]: Unable to convert swap to a device
2020-06-18 06:40:04,887 - cc_mounts.py[DEBUG]: changed default device swap => None
2020-06-18 06:40:04,887 - cc_mounts.py[DEBUG]: Ignoring nonexistent default named mount swap
2020-06-18 06:40:04,887 - cc_mounts.py[DEBUG]: no need to setup swap
2020-06-18 06:40:04,887 - cc_mounts.py[DEBUG]: No modifications to fstab needed
2020-06-18 06:40:04,887 - handlers.py[DEBUG]: finish: init-network/config-mounts: SUCCESS: config-mounts ran successfully
2020-06-18 06:40:04,887 - stages.py[DEBUG]: Running module set_hostname (<module 'cloudinit.config.cc_set_hostname' from '/usr/lib/python3/dist-packages/cloudinit/config/cc_set_hostname.py'>) with frequency once-per-instance
2020-06-18 06:40:04,887 - handlers.py[DEBUG]: start: init-network/config-set_hostname: running config-set_hostname with frequency once-per-instance
2020-06-18 06:40:04,887 - util.py[DEBUG]: Writing to /var/lib/cloud/instances/i-0c2ccc2ca413bce53/sem/config_set_hostname - wb: [644] 24 bytes
2020-06-18 06:40:04,888 - helpers.py[DEBUG]: Running config-set_hostname using lock (<FileLock using file '/var/lib/cloud/instances/i-0c2ccc2ca413bce53/sem/config_set_hostname'>)
2020-06-18 06:40:04,888 - util.py[DEBUG]: Reading from /var/lib/cloud/data/set-hostname (quiet=False)
2020-06-18 06:40:04,888 - util.py[DEBUG]: Read 95 bytes from /var/lib/cloud/data/set-hostname
2020-06-18 06:40:04,888 - cc_set_hostname.py[DEBUG]: No hostname changes. Skipping set-hostname
2020-06-18 06:40:04,888 - handlers.py[DEBUG]: finish: init-network/config-set_hostname: SUCCESS: config-set_hostname ran successfully
2020-06-18 06:40:04,888 - stages.py[DEBUG]: Running module update_hostname (<module 'cloudinit.config.cc_update_hostname' from '/usr/lib/python3/dist-packages/cloudinit/config/cc_update_hostname.py'>) with frequency always
2020-06-18 06:40:04,889 - handlers.py[DEBUG]: start: init-network/config-update_hostname: running config-update_hostname with frequency always
2020-06-18 06:40:04,889 - helpers.py[DEBUG]: Running config-update_hostname using lock (<cloudinit.helpers.DummyLock object at 0x7fdcfe752898>)
2020-06-18 06:40:04,889 - cc_update_hostname.py[DEBUG]: Updating hostname to ip-172-31-24-65.ap-southeast-2.compute.internal (ip-172-31-24-65)
2020-06-18 06:40:04,889 - util.py[DEBUG]: Reading from /etc/hostname (quiet=False)
2020-06-18 06:40:04,889 - util.py[DEBUG]: Read 16 bytes from /etc/hostname
2020-06-18 06:40:04,889 - __init__.py[DEBUG]: Attempting to update hostname to ip-172-31-24-65 in 1 files
2020-06-18 06:40:04,889 - util.py[DEBUG]: Reading from /var/lib/cloud/data/previous-hostname (quiet=False)
2020-06-18 06:40:04,889 - util.py[DEBUG]: Writing to /var/lib/cloud/data/previous-hostname - wb: [644] 16 bytes
2020-06-18 06:40:04,889 - handlers.py[DEBUG]: finish: init-network/config-update_hostname: SUCCESS: config-update_hostname ran successfully
2020-06-18 06:40:04,890 - stages.py[DEBUG]: Running module update_etc_hosts (<module 'cloudinit.config.cc_update_etc_hosts' from '/usr/lib/python3/dist-packages/cloudinit/config/cc_update_etc_hosts.py'>) with frequency always
2020-06-18 06:40:04,890 - handlers.py[DEBUG]: start: init-network/config-update_etc_hosts: running config-update_etc_hosts with frequency always
2020-06-18 06:40:04,890 - helpers.py[DEBUG]: Running config-update_etc_hosts using lock (<cloudinit.helpers.DummyLock object at 0x7fdcfe752cf8>)
2020-06-18 06:40:04,890 - cc_update_etc_hosts.py[DEBUG]: Configuration option 'manage_etc_hosts' is not set, not managing /etc/hosts in module update_etc_hosts
2020-06-18 06:40:04,890 - handlers.py[DEBUG]: finish: init-network/config-update_etc_hosts: SUCCESS: config-update_etc_hosts ran successfully
2020-06-18 06:40:04,890 - stages.py[DEBUG]: Running module ca-certs (<module 'cloudinit.config.cc_ca_certs' from '/usr/lib/python3/dist-packages/cloudinit/config/cc_ca_certs.py'>) with frequency once-per-instance
2020-06-18 06:40:04,890 - handlers.py[DEBUG]: start: init-network/config-ca-certs: running config-ca-certs with frequency once-per-instance
2020-06-18 06:40:04,890 - util.py[DEBUG]: Writing to /var/lib/cloud/instances/i-0c2ccc2ca413bce53/sem/config_ca_certs - wb: [644] 24 bytes
2020-06-18 06:40:04,891 - helpers.py[DEBUG]: Running config-ca-certs using lock (<FileLock using file '/var/lib/cloud/instances/i-0c2ccc2ca413bce53/sem/config_ca_certs'>)
2020-06-18 06:40:04,891 - cc_ca_certs.py[DEBUG]: Skipping module named ca-certs, no 'ca-certs' key in configuration
2020-06-18 06:40:04,891 - handlers.py[DEBUG]: finish: init-network/config-ca-certs: SUCCESS: config-ca-certs ran successfully
2020-06-18 06:40:04,891 - stages.py[DEBUG]: Running module rsyslog (<module 'cloudinit.config.cc_rsyslog' from '/usr/lib/python3/dist-packages/cloudinit/config/cc_rsyslog.py'>) with frequency once-per-instance
2020-06-18 06:40:04,897 - handlers.py[DEBUG]: start: init-network/config-rsyslog: running config-rsyslog with frequency once-per-instance
2020-06-18 06:40:04,898 - util.py[DEBUG]: Writing to /var/lib/cloud/instances/i-0c2ccc2ca413bce53/sem/config_rsyslog - wb: [644] 24 bytes
2020-06-18 06:40:04,898 - helpers.py[DEBUG]: Running config-rsyslog using lock (<FileLock using file '/var/lib/cloud/instances/i-0c2ccc2ca413bce53/sem/config_rsyslog'>)
2020-06-18 06:40:04,898 - cc_rsyslog.py[DEBUG]: Skipping module named rsyslog, no 'rsyslog' key in configuration
2020-06-18 06:40:04,898 - handlers.py[DEBUG]: finish: init-network/config-rsyslog: SUCCESS: config-rsyslog ran successfully
2020-06-18 06:40:04,898 - stages.py[DEBUG]: Running module users-groups (<module 'cloudinit.config.cc_users_groups' from '/usr/lib/python3/dist-packages/cloudinit/config/cc_users_groups.py'>) with frequency once-per-instance
2020-06-18 06:40:04,898 - handlers.py[DEBUG]: start: init-network/config-users-groups: running config-users-groups with frequency once-per-instance
2020-06-18 06:40:04,899 - util.py[DEBUG]: Writing to /var/lib/cloud/instances/i-0c2ccc2ca413bce53/sem/config_users_groups - wb: [644] 24 bytes
2020-06-18 06:40:04,899 - helpers.py[DEBUG]: Running config-users-groups using lock (<FileLock using file '/var/lib/cloud/instances/i-0c2ccc2ca413bce53/sem/config_users_groups'>)
2020-06-18 06:40:04,900 - util.py[DEBUG]: Reading from /etc/os-release (quiet=True)
2020-06-18 06:40:04,900 - util.py[DEBUG]: Read 386 bytes from /etc/os-release
2020-06-18 06:40:04,900 - util.py[DEBUG]: Reading from /etc/system-image/channel.ini (quiet=True)
2020-06-18 06:40:04,900 - util.py[DEBUG]: Read 0 bytes from /etc/system-image/channel.ini
2020-06-18 06:40:04,901 - __init__.py[DEBUG]: Adding user ubuntu
2020-06-18 06:40:04,901 - util.py[DEBUG]: Running hidden command to protect sensitive input/output logstring: ['useradd', 'ubuntu', '--comment', 'Ubuntu', '--groups', 'adm,audio,cdrom,dialout,dip,floppy,lxd,netdev,plugdev,sudo,video', '--shell', '/bin/bash', '-m']
2020-06-18 06:40:05,112 - util.py[DEBUG]: Running command ['passwd', '-l', 'ubuntu'] with allowed return codes [0] (shell=False, capture=True)
2020-06-18 06:40:05,135 - util.py[DEBUG]: Reading from /etc/sudoers (quiet=False)
2020-06-18 06:40:05,141 - util.py[DEBUG]: Read 755 bytes from /etc/sudoers
2020-06-18 06:40:05,142 - util.py[DEBUG]: Writing to /etc/sudoers.d/90-cloud-init-users - wb: [440] 152 bytes
2020-06-18 06:40:05,143 - handlers.py[DEBUG]: finish: init-network/config-users-groups: SUCCESS: config-users-groups ran successfully
2020-06-18 06:40:05,143 - stages.py[DEBUG]: Running module ssh (<module 'cloudinit.config.cc_ssh' from '/usr/lib/python3/dist-packages/cloudinit/config/cc_ssh.py'>) with frequency once-per-instance
2020-06-18 06:40:05,143 - handlers.py[DEBUG]: start: init-network/config-ssh: running config-ssh with frequency once-per-instance
2020-06-18 06:40:05,143 - util.py[DEBUG]: Writing to /var/lib/cloud/instances/i-0c2ccc2ca413bce53/sem/config_ssh - wb: [644] 24 bytes
2020-06-18 06:40:05,144 - helpers.py[DEBUG]: Running config-ssh using lock (<FileLock using file '/var/lib/cloud/instances/i-0c2ccc2ca413bce53/sem/config_ssh'>)
2020-06-18 06:40:05,144 - util.py[DEBUG]: Running command ['ssh-keygen', '-t', 'rsa', '-N', '', '-f', '/etc/ssh/ssh_host_rsa_key'] with allowed return codes [0] (shell=False, capture=True)
2020-06-18 06:40:05,237 - util.py[DEBUG]: Running command ['ssh-keygen', '-t', 'dsa', '-N', '', '-f', '/etc/ssh/ssh_host_dsa_key'] with allowed return codes [0] (shell=False, capture=True)
2020-06-18 06:40:05,278 - util.py[DEBUG]: Running command ['ssh-keygen', '-t', 'ecdsa', '-N', '', '-f', '/etc/ssh/ssh_host_ecdsa_key'] with allowed return codes [0] (shell=False, capture=True)
2020-06-18 06:40:05,283 - util.py[DEBUG]: Running command ['ssh-keygen', '-t', 'ed25519', '-N', '', '-f', '/etc/ssh/ssh_host_ed25519_key'] with allowed return codes [0] (shell=False, capture=True)
2020-06-18 06:40:05,289 - util.py[DEBUG]: Changing the ownership of /home/ubuntu/.ssh to 1000:1000
2020-06-18 06:40:05,289 - util.py[DEBUG]: Reading from /etc/ssh/sshd_config (quiet=False)
2020-06-18 06:40:05,291 - util.py[DEBUG]: Read 3262 bytes from /etc/ssh/sshd_config
2020-06-18 06:40:05,291 - util.py[DEBUG]: Writing to /home/ubuntu/.ssh/authorized_keys - wb: [600] 394 bytes
2020-06-18 06:40:05,292 - util.py[DEBUG]: Changing the ownership of /home/ubuntu/.ssh/authorized_keys to 1000:1000
2020-06-18 06:40:05,292 - util.py[DEBUG]: Changing the ownership of /root/.ssh to 0:0
2020-06-18 06:40:05,292 - util.py[DEBUG]: Reading from /etc/ssh/sshd_config (quiet=False)
2020-06-18 06:40:05,293 - util.py[DEBUG]: Read 3262 bytes from /etc/ssh/sshd_config
2020-06-18 06:40:05,293 - util.py[DEBUG]: Writing to /root/.ssh/authorized_keys - wb: [600] 549 bytes
2020-06-18 06:40:05,293 - util.py[DEBUG]: Changing the ownership of /root/.ssh/authorized_keys to 0:0
2020-06-18 06:40:05,294 - handlers.py[DEBUG]: finish: init-network/config-ssh: SUCCESS: config-ssh ran successfully
2020-06-18 06:40:05,294 - main.py[DEBUG]: Ran 15 modules with 0 failures
2020-06-18 06:40:05,294 - util.py[DEBUG]: Reading from /proc/uptime (quiet=False)
2020-06-18 06:40:05,294 - util.py[DEBUG]: Read 11 bytes from /proc/uptime
2020-06-18 06:40:05,294 - util.py[DEBUG]: cloud-init mode 'init' took 0.871 seconds (0.87)
2020-06-18 06:40:05,295 - handlers.py[DEBUG]: finish: init-network: SUCCESS: searching for network datasources
2020-06-18 06:40:20,235 - util.py[DEBUG]: Cloud-init v. 18.5-45-g3554ffe8-0ubuntu1~18.04.1 running 'modules:config' at Thu, 18 Jun 2020 06:40:20 +0000. Up 26.46 seconds.
2020-06-18 06:40:20,252 - stages.py[DEBUG]: Using distro class <class 'cloudinit.distros.ubuntu.Distro'>
2020-06-18 06:40:20,253 - stages.py[DEBUG]: Running module emit_upstart (<module 'cloudinit.config.cc_emit_upstart' from '/usr/lib/python3/dist-packages/cloudinit/config/cc_emit_upstart.py'>) with frequency always
2020-06-18 06:40:20,253 - handlers.py[DEBUG]: start: modules-config/config-emit_upstart: running config-emit_upstart with frequency always
2020-06-18 06:40:20,253 - helpers.py[DEBUG]: Running config-emit_upstart using lock (<cloudinit.helpers.DummyLock object at 0x7f0034c66ba8>)
2020-06-18 06:40:20,253 - cc_emit_upstart.py[DEBUG]: no /sbin/initctl located
2020-06-18 06:40:20,253 - cc_emit_upstart.py[DEBUG]: not upstart system, 'emit_upstart' disabled
2020-06-18 06:40:20,253 - handlers.py[DEBUG]: finish: modules-config/config-emit_upstart: SUCCESS: config-emit_upstart ran successfully
2020-06-18 06:40:20,253 - stages.py[DEBUG]: Running module snap (<module 'cloudinit.config.cc_snap' from '/usr/lib/python3/dist-packages/cloudinit/config/cc_snap.py'>) with frequency once-per-instance
2020-06-18 06:40:20,253 - handlers.py[DEBUG]: start: modules-config/config-snap: running config-snap with frequency once-per-instance
2020-06-18 06:40:20,253 - util.py[DEBUG]: Writing to /var/lib/cloud/instances/i-0c2ccc2ca413bce53/sem/config_snap - wb: [644] 25 bytes
2020-06-18 06:40:20,254 - helpers.py[DEBUG]: Running config-snap using lock (<FileLock using file '/var/lib/cloud/instances/i-0c2ccc2ca413bce53/sem/config_snap'>)
2020-06-18 06:40:20,254 - cc_snap.py[DEBUG]: Skipping module named snap, no 'snap' key in configuration
2020-06-18 06:40:20,254 - handlers.py[DEBUG]: finish: modules-config/config-snap: SUCCESS: config-snap ran successfully
2020-06-18 06:40:20,254 - stages.py[DEBUG]: Running module snap_config (<module 'cloudinit.config.cc_snap_config' from '/usr/lib/python3/dist-packages/cloudinit/config/cc_snap_config.py'>) with frequency once-per-instance
2020-06-18 06:40:20,254 - handlers.py[DEBUG]: start: modules-config/config-snap_config: running config-snap_config with frequency once-per-instance
2020-06-18 06:40:20,254 - util.py[DEBUG]: Writing to /var/lib/cloud/instances/i-0c2ccc2ca413bce53/sem/config_snap_config - wb: [644] 25 bytes
2020-06-18 06:40:20,255 - helpers.py[DEBUG]: Running config-snap_config using lock (<FileLock using file '/var/lib/cloud/instances/i-0c2ccc2ca413bce53/sem/config_snap_config'>)
2020-06-18 06:40:20,255 - cc_snap_config.py[DEBUG]: No snappy config provided, skipping
2020-06-18 06:40:20,255 - handlers.py[DEBUG]: finish: modules-config/config-snap_config: SUCCESS: config-snap_config ran successfully
2020-06-18 06:40:20,255 - stages.py[DEBUG]: Running module ssh-import-id (<module 'cloudinit.config.cc_ssh_import_id' from '/usr/lib/python3/dist-packages/cloudinit/config/cc_ssh_import_id.py'>) with frequency once-per-instance
2020-06-18 06:40:20,255 - handlers.py[DEBUG]: start: modules-config/config-ssh-import-id: running config-ssh-import-id with frequency once-per-instance
2020-06-18 06:40:20,255 - util.py[DEBUG]: Writing to /var/lib/cloud/instances/i-0c2ccc2ca413bce53/sem/config_ssh_import_id - wb: [644] 25 bytes
2020-06-18 06:40:20,256 - helpers.py[DEBUG]: Running config-ssh-import-id using lock (<FileLock using file '/var/lib/cloud/instances/i-0c2ccc2ca413bce53/sem/config_ssh_import_id'>)
2020-06-18 06:40:20,256 - handlers.py[DEBUG]: finish: modules-config/config-ssh-import-id: SUCCESS: config-ssh-import-id ran successfully
2020-06-18 06:40:20,256 - stages.py[DEBUG]: Running module locale (<module 'cloudinit.config.cc_locale' from '/usr/lib/python3/dist-packages/cloudinit/config/cc_locale.py'>) with frequency once-per-instance
2020-06-18 06:40:20,256 - handlers.py[DEBUG]: start: modules-config/config-locale: running config-locale with frequency once-per-instance
2020-06-18 06:40:20,256 - util.py[DEBUG]: Writing to /var/lib/cloud/instances/i-0c2ccc2ca413bce53/sem/config_locale - wb: [644] 25 bytes
2020-06-18 06:40:20,257 - helpers.py[DEBUG]: Running config-locale using lock (<FileLock using file '/var/lib/cloud/instances/i-0c2ccc2ca413bce53/sem/config_locale'>)
2020-06-18 06:40:20,257 - util.py[DEBUG]: Reading from /etc/default/locale (quiet=False)
2020-06-18 06:40:20,257 - util.py[DEBUG]: Read 13 bytes from /etc/default/locale
2020-06-18 06:40:20,257 - cc_locale.py[DEBUG]: Setting locale to C.UTF-8
2020-06-18 06:40:20,257 - debian.py[DEBUG]: System has 'LANG=C.UTF-8' requested 'C.UTF-8', skipping regeneration.
2020-06-18 06:40:20,257 - handlers.py[DEBUG]: finish: modules-config/config-locale: SUCCESS: config-locale ran successfully
2020-06-18 06:40:20,257 - stages.py[DEBUG]: Running module set-passwords (<module 'cloudinit.config.cc_set_passwords' from '/usr/lib/python3/dist-packages/cloudinit/config/cc_set_passwords.py'>) with frequency once-per-instance
2020-06-18 06:40:20,257 - handlers.py[DEBUG]: start: modules-config/config-set-passwords: running config-set-passwords with frequency once-per-instance
2020-06-18 06:40:20,257 - util.py[DEBUG]: Writing to /var/lib/cloud/instances/i-0c2ccc2ca413bce53/sem/config_set_passwords - wb: [644] 25 bytes
2020-06-18 06:40:20,258 - helpers.py[DEBUG]: Running config-set-passwords using lock (<FileLock using file '/var/lib/cloud/instances/i-0c2ccc2ca413bce53/sem/config_set_passwords'>)
2020-06-18 06:40:20,258 - cc_set_passwords.py[DEBUG]: Leaving ssh config 'PasswordAuthentication' unchanged. ssh_pwauth=None
2020-06-18 06:40:20,258 - handlers.py[DEBUG]: finish: modules-config/config-set-passwords: SUCCESS: config-set-passwords ran successfully
2020-06-18 06:40:20,258 - stages.py[DEBUG]: Running module grub-dpkg (<module 'cloudinit.config.cc_grub_dpkg' from '/usr/lib/python3/dist-packages/cloudinit/config/cc_grub_dpkg.py'>) with frequency once-per-instance
2020-06-18 06:40:20,258 - handlers.py[DEBUG]: start: modules-config/config-grub-dpkg: running config-grub-dpkg with frequency once-per-instance
2020-06-18 06:40:20,258 - util.py[DEBUG]: Writing to /var/lib/cloud/instances/i-0c2ccc2ca413bce53/sem/config_grub_dpkg - wb: [644] 25 bytes
2020-06-18 06:40:20,259 - helpers.py[DEBUG]: Running config-grub-dpkg using lock (<FileLock using file '/var/lib/cloud/instances/i-0c2ccc2ca413bce53/sem/config_grub_dpkg'>)
2020-06-18 06:40:20,259 - cc_grub_dpkg.py[DEBUG]: Setting grub debconf-set-selections with '/dev/xvda','false'
2020-06-18 06:40:20,259 - util.py[DEBUG]: Running command ['debconf-set-selections'] with allowed return codes [0] (shell=False, capture=True)
2020-06-18 06:40:20,457 - handlers.py[DEBUG]: finish: modules-config/config-grub-dpkg: SUCCESS: config-grub-dpkg ran successfully
2020-06-18 06:40:20,458 - stages.py[DEBUG]: Running module apt-pipelining (<module 'cloudinit.config.cc_apt_pipelining' from '/usr/lib/python3/dist-packages/cloudinit/config/cc_apt_pipelining.py'>) with frequency once-per-instance
2020-06-18 06:40:20,458 - handlers.py[DEBUG]: start: modules-config/config-apt-pipelining: running config-apt-pipelining with frequency once-per-instance
2020-06-18 06:40:20,458 - util.py[DEBUG]: Writing to /var/lib/cloud/instances/i-0c2ccc2ca413bce53/sem/config_apt_pipelining - wb: [644] 25 bytes
2020-06-18 06:40:20,459 - helpers.py[DEBUG]: Running config-apt-pipelining using lock (<FileLock using file '/var/lib/cloud/instances/i-0c2ccc2ca413bce53/sem/config_apt_pipelining'>)
2020-06-18 06:40:20,459 - handlers.py[DEBUG]: finish: modules-config/config-apt-pipelining: SUCCESS: config-apt-pipelining ran successfully
2020-06-18 06:40:20,459 - stages.py[DEBUG]: Running module apt-configure (<module 'cloudinit.config.cc_apt_configure' from '/usr/lib/python3/dist-packages/cloudinit/config/cc_apt_configure.py'>) with frequency once-per-instance
2020-06-18 06:40:20,459 - handlers.py[DEBUG]: start: modules-config/config-apt-configure: running config-apt-configure with frequency once-per-instance
2020-06-18 06:40:20,459 - util.py[DEBUG]: Writing to /var/lib/cloud/instances/i-0c2ccc2ca413bce53/sem/config_apt_configure - wb: [644] 25 bytes
2020-06-18 06:40:20,460 - helpers.py[DEBUG]: Running config-apt-configure using lock (<FileLock using file '/var/lib/cloud/instances/i-0c2ccc2ca413bce53/sem/config_apt_configure'>)
2020-06-18 06:40:20,460 - cc_apt_configure.py[DEBUG]: debconf_selections was not set in config
2020-06-18 06:40:20,460 - util.py[DEBUG]: Reading from /etc/os-release (quiet=True)
2020-06-18 06:40:20,460 - util.py[DEBUG]: Read 386 bytes from /etc/os-release
2020-06-18 06:40:20,460 - util.py[DEBUG]: Reading from /etc/system-image/channel.ini (quiet=True)
2020-06-18 06:40:20,460 - util.py[DEBUG]: Read 0 bytes from /etc/system-image/channel.ini
2020-06-18 06:40:20,461 - cc_apt_configure.py[DEBUG]: handling apt config: {}
2020-06-18 06:40:20,461 - util.py[DEBUG]: Running command ['lsb_release', '--all'] with allowed return codes [0] (shell=False, capture=True)
2020-06-18 06:40:20,519 - util.py[DEBUG]: Running command ['dpkg', '--print-architecture'] with allowed return codes [0] (shell=False, capture=True)
2020-06-18 06:40:20,522 - cc_apt_configure.py[DEBUG]: got primary mirror: None
2020-06-18 06:40:20,523 - cc_apt_configure.py[DEBUG]: got security mirror: None
2020-06-18 06:40:20,523 - util.py[DEBUG]: Running command ['dpkg', '--print-architecture'] with allowed return codes [0] (shell=False, capture=True)
2020-06-18 06:40:20,718 - util.py[DEBUG]: Resolving URL: http://ap-southeast-2.ec2.archive.ubuntu.com/ubuntu/ took 0.192 seconds
2020-06-18 06:40:20,718 - __init__.py[DEBUG]: filtered distro mirror info: {'primary': 'http://ap-southeast-2.ec2.archive.ubuntu.com/ubuntu/', 'security': 'http://security.ubuntu.com/ubuntu'}
2020-06-18 06:40:20,718 - cc_apt_configure.py[DEBUG]: Apt Mirror info: {'primary': 'http://ap-southeast-2.ec2.archive.ubuntu.com/ubuntu/', 'security': 'http://security.ubuntu.com/ubuntu', 'PRIMARY': 'http://ap-southeast-2.ec2.archive.ubuntu.com/ubuntu/', 'SECURITY': 'http://security.ubuntu.com/ubuntu', 'MIRROR': 'http://ap-southeast-2.ec2.archive.ubuntu.com/ubuntu/'}
2020-06-18 06:40:20,718 - cc_apt_configure.py[INFO]: No custom template provided, fall back to builtin
2020-06-18 06:40:20,719 - util.py[DEBUG]: Reading from /etc/cloud/templates/sources.list.ubuntu.tmpl (quiet=False)
2020-06-18 06:40:20,719 - util.py[DEBUG]: Read 2858 bytes from /etc/cloud/templates/sources.list.ubuntu.tmpl
2020-06-18 06:40:20,727 - util.py[DEBUG]: Writing to /etc/apt/sources.list - wb: [644] 3422 bytes
2020-06-18 06:40:20,728 - util.py[DEBUG]: Running command ['dpkg', '--print-architecture'] with allowed return codes [0] (shell=False, capture=True)
2020-06-18 06:40:20,733 - cc_apt_configure.py[DEBUG]: Renaming apt list /var/lib/apt/lists/archive.ubuntu.com_ubuntu_dists_bionic_restricted_i18n_Translation-en to /var/lib/apt/lists/ap-southeast-2.ec2.archive.ubuntu.com_ubuntu_dists_bionic_restricted_i18n_Translation-en
2020-06-18 06:40:20,736 - cc_apt_configure.py[DEBUG]: Renaming apt list /var/lib/apt/lists/archive.ubuntu.com_ubuntu_dists_bionic_InRelease to /var/lib/apt/lists/ap-southeast-2.ec2.archive.ubuntu.com_ubuntu_dists_bionic_InRelease
2020-06-18 06:40:20,736 - cc_apt_configure.py[DEBUG]: Renaming apt list /var/lib/apt/lists/archive.ubuntu.com_ubuntu_dists_bionic_main_i18n_Translation-en to /var/lib/apt/lists/ap-southeast-2.ec2.archive.ubuntu.com_ubuntu_dists_bionic_main_i18n_Translation-en
2020-06-18 06:40:20,736 - cc_apt_configure.py[DEBUG]: Renaming apt list /var/lib/apt/lists/archive.ubuntu.com_ubuntu_dists_bionic-updates_restricted_binary-amd64_Packages to /var/lib/apt/lists/ap-southeast-2.ec2.archive.ubuntu.com_ubuntu_dists_bionic-updates_restricted_binary-amd64_Packages
2020-06-18 06:40:20,736 - cc_apt_configure.py[DEBUG]: Renaming apt list /var/lib/apt/lists/archive.ubuntu.com_ubuntu_dists_bionic-updates_restricted_i18n_Translation-en to /var/lib/apt/lists/ap-southeast-2.ec2.archive.ubuntu.com_ubuntu_dists_bionic-updates_restricted_i18n_Translation-en
2020-06-18 06:40:20,736 - cc_apt_configure.py[DEBUG]: Renaming apt list /var/lib/apt/lists/archive.ubuntu.com_ubuntu_dists_bionic_restricted_binary-amd64_Packages to /var/lib/apt/lists/ap-southeast-2.ec2.archive.ubuntu.com_ubuntu_dists_bionic_restricted_binary-amd64_Packages
2020-06-18 06:40:20,736 - cc_apt_configure.py[DEBUG]: Renaming apt list /var/lib/apt/lists/archive.ubuntu.com_ubuntu_dists_bionic-updates_main_i18n_Translation-en to /var/lib/apt/lists/ap-southeast-2.ec2.archive.ubuntu.com_ubuntu_dists_bionic-updates_main_i18n_Translation-en
2020-06-18 06:40:20,736 - cc_apt_configure.py[DEBUG]: Renaming apt list /var/lib/apt/lists/archive.ubuntu.com_ubuntu_dists_bionic-updates_InRelease to /var/lib/apt/lists/ap-southeast-2.ec2.archive.ubuntu.com_ubuntu_dists_bionic-updates_InRelease
2020-06-18 06:40:20,736 - cc_apt_configure.py[DEBUG]: Renaming apt list /var/lib/apt/lists/archive.ubuntu.com_ubuntu_dists_bionic_main_binary-amd64_Packages to /var/lib/apt/lists/ap-southeast-2.ec2.archive.ubuntu.com_ubuntu_dists_bionic_main_binary-amd64_Packages
2020-06-18 06:40:20,736 - cc_apt_configure.py[DEBUG]: Renaming apt list /var/lib/apt/lists/archive.ubuntu.com_ubuntu_dists_bionic-updates_main_binary-amd64_Packages to /var/lib/apt/lists/ap-southeast-2.ec2.archive.ubuntu.com_ubuntu_dists_bionic-updates_main_binary-amd64_Packages
2020-06-18 06:40:20,736 - handlers.py[DEBUG]: finish: modules-config/config-apt-configure: SUCCESS: config-apt-configure ran successfully
2020-06-18 06:40:20,737 - stages.py[DEBUG]: Running module ubuntu-advantage (<module 'cloudinit.config.cc_ubuntu_advantage' from '/usr/lib/python3/dist-packages/cloudinit/config/cc_ubuntu_advantage.py'>) with frequency once-per-instance
2020-06-18 06:40:20,737 - handlers.py[DEBUG]: start: modules-config/config-ubuntu-advantage: running config-ubuntu-advantage with frequency once-per-instance
2020-06-18 06:40:20,737 - util.py[DEBUG]: Writing to /var/lib/cloud/instances/i-0c2ccc2ca413bce53/sem/config_ubuntu_advantage - wb: [644] 25 bytes
2020-06-18 06:40:20,737 - helpers.py[DEBUG]: Running config-ubuntu-advantage using lock (<FileLock using file '/var/lib/cloud/instances/i-0c2ccc2ca413bce53/sem/config_ubuntu_advantage'>)
2020-06-18 06:40:20,738 - cc_ubuntu_advantage.py[DEBUG]: Skipping module named ubuntu-advantage, no 'ubuntu-advantage' key in configuration
2020-06-18 06:40:20,738 - handlers.py[DEBUG]: finish: modules-config/config-ubuntu-advantage: SUCCESS: config-ubuntu-advantage ran successfully
2020-06-18 06:40:20,738 - stages.py[DEBUG]: Running module ntp (<module 'cloudinit.config.cc_ntp' from '/usr/lib/python3/dist-packages/cloudinit/config/cc_ntp.py'>) with frequency once-per-instance
2020-06-18 06:40:20,738 - handlers.py[DEBUG]: start: modules-config/config-ntp: running config-ntp with frequency once-per-instance
2020-06-18 06:40:20,738 - util.py[DEBUG]: Writing to /var/lib/cloud/instances/i-0c2ccc2ca413bce53/sem/config_ntp - wb: [644] 24 bytes
2020-06-18 06:40:20,738 - helpers.py[DEBUG]: Running config-ntp using lock (<FileLock using file '/var/lib/cloud/instances/i-0c2ccc2ca413bce53/sem/config_ntp'>)
2020-06-18 06:40:20,738 - cc_ntp.py[DEBUG]: Skipping module named ntp, not present or disabled by cfg
2020-06-18 06:40:20,739 - handlers.py[DEBUG]: finish: modules-config/config-ntp: SUCCESS: config-ntp ran successfully
2020-06-18 06:40:20,739 - stages.py[DEBUG]: Running module timezone (<module 'cloudinit.config.cc_timezone' from '/usr/lib/python3/dist-packages/cloudinit/config/cc_timezone.py'>) with frequency once-per-instance
2020-06-18 06:40:20,739 - handlers.py[DEBUG]: start: modules-config/config-timezone: running config-timezone with frequency once-per-instance
2020-06-18 06:40:20,739 - util.py[DEBUG]: Writing to /var/lib/cloud/instances/i-0c2ccc2ca413bce53/sem/config_timezone - wb: [644] 25 bytes
2020-06-18 06:40:20,739 - helpers.py[DEBUG]: Running config-timezone using lock (<FileLock using file '/var/lib/cloud/instances/i-0c2ccc2ca413bce53/sem/config_timezone'>)
2020-06-18 06:40:20,739 - cc_timezone.py[DEBUG]: Skipping module named timezone, no 'timezone' specified
2020-06-18 06:40:20,739 - handlers.py[DEBUG]: finish: modules-config/config-timezone: SUCCESS: config-timezone ran successfully
2020-06-18 06:40:20,740 - stages.py[DEBUG]: Running module disable-ec2-metadata (<module 'cloudinit.config.cc_disable_ec2_metadata' from '/usr/lib/python3/dist-packages/cloudinit/config/cc_disable_ec2_metadata.py'>) with frequency always
2020-06-18 06:40:20,740 - handlers.py[DEBUG]: start: modules-config/config-disable-ec2-metadata: running config-disable-ec2-metadata with frequency always
2020-06-18 06:40:20,740 - helpers.py[DEBUG]: Running config-disable-ec2-metadata using lock (<cloudinit.helpers.DummyLock object at 0x7f0034c5ea90>)
2020-06-18 06:40:20,740 - cc_disable_ec2_metadata.py[DEBUG]: Skipping module named disable-ec2-metadata, disabling the ec2 route not enabled
2020-06-18 06:40:20,740 - handlers.py[DEBUG]: finish: modules-config/config-disable-ec2-metadata: SUCCESS: config-disable-ec2-metadata ran successfully
2020-06-18 06:40:20,740 - stages.py[DEBUG]: Running module runcmd (<module 'cloudinit.config.cc_runcmd' from '/usr/lib/python3/dist-packages/cloudinit/config/cc_runcmd.py'>) with frequency once-per-instance
2020-06-18 06:40:20,740 - handlers.py[DEBUG]: start: modules-config/config-runcmd: running config-runcmd with frequency once-per-instance
2020-06-18 06:40:20,740 - util.py[DEBUG]: Writing to /var/lib/cloud/instances/i-0c2ccc2ca413bce53/sem/config_runcmd - wb: [644] 25 bytes
2020-06-18 06:40:20,741 - helpers.py[DEBUG]: Running config-runcmd using lock (<FileLock using file '/var/lib/cloud/instances/i-0c2ccc2ca413bce53/sem/config_runcmd'>)
2020-06-18 06:40:20,741 - cc_runcmd.py[DEBUG]: Skipping module named runcmd, no 'runcmd' key in configuration
2020-06-18 06:40:20,741 - handlers.py[DEBUG]: finish: modules-config/config-runcmd: SUCCESS: config-runcmd ran successfully
2020-06-18 06:40:20,741 - stages.py[DEBUG]: Running module byobu (<module 'cloudinit.config.cc_byobu' from '/usr/lib/python3/dist-packages/cloudinit/config/cc_byobu.py'>) with frequency once-per-instance
2020-06-18 06:40:20,741 - handlers.py[DEBUG]: start: modules-config/config-byobu: running config-byobu with frequency once-per-instance
2020-06-18 06:40:20,741 - util.py[DEBUG]: Writing to /var/lib/cloud/instances/i-0c2ccc2ca413bce53/sem/config_byobu - wb: [644] 25 bytes
2020-06-18 06:40:20,741 - helpers.py[DEBUG]: Running config-byobu using lock (<FileLock using file '/var/lib/cloud/instances/i-0c2ccc2ca413bce53/sem/config_byobu'>)
2020-06-18 06:40:20,741 - cc_byobu.py[DEBUG]: Skipping module named byobu, no 'byobu' values found
2020-06-18 06:40:20,742 - handlers.py[DEBUG]: finish: modules-config/config-byobu: SUCCESS: config-byobu ran successfully
2020-06-18 06:40:20,742 - main.py[DEBUG]: Ran 15 modules with 0 failures
2020-06-18 06:40:20,742 - util.py[DEBUG]: Reading from /proc/uptime (quiet=False)
2020-06-18 06:40:20,742 - util.py[DEBUG]: Read 11 bytes from /proc/uptime
2020-06-18 06:40:20,742 - util.py[DEBUG]: cloud-init mode 'modules' took 0.602 seconds (0.60)
2020-06-18 06:40:20,743 - handlers.py[DEBUG]: finish: modules-config: SUCCESS: running modules for config
2020-06-18 06:40:21,271 - util.py[DEBUG]: Cloud-init v. 18.5-45-g3554ffe8-0ubuntu1~18.04.1 running 'modules:final' at Thu, 18 Jun 2020 06:40:21 +0000. Up 27.51 seconds.
2020-06-18 06:40:21,288 - stages.py[DEBUG]: Using distro class <class 'cloudinit.distros.ubuntu.Distro'>
2020-06-18 06:40:21,289 - stages.py[DEBUG]: Running module snappy (<module 'cloudinit.config.cc_snappy' from '/usr/lib/python3/dist-packages/cloudinit/config/cc_snappy.py'>) with frequency once-per-instance
2020-06-18 06:40:21,289 - handlers.py[DEBUG]: start: modules-final/config-snappy: running config-snappy with frequency once-per-instance
2020-06-18 06:40:21,290 - util.py[DEBUG]: Writing to /var/lib/cloud/instances/i-0c2ccc2ca413bce53/sem/config_snappy - wb: [644] 25 bytes
2020-06-18 06:40:21,290 - helpers.py[DEBUG]: Running config-snappy using lock (<FileLock using file '/var/lib/cloud/instances/i-0c2ccc2ca413bce53/sem/config_snappy'>)
2020-06-18 06:40:21,290 - util.py[DEBUG]: Reading from /etc/os-release (quiet=True)
2020-06-18 06:40:21,290 - util.py[DEBUG]: Read 386 bytes from /etc/os-release
2020-06-18 06:40:21,291 - util.py[DEBUG]: Reading from /etc/system-image/channel.ini (quiet=True)
2020-06-18 06:40:21,291 - util.py[DEBUG]: Read 0 bytes from /etc/system-image/channel.ini
2020-06-18 06:40:21,291 - cc_snappy.py[DEBUG]: snappy: 'auto' mode, and system not snappy
2020-06-18 06:40:21,291 - handlers.py[DEBUG]: finish: modules-final/config-snappy: SUCCESS: config-snappy ran successfully
2020-06-18 06:40:21,291 - stages.py[DEBUG]: Running module package-update-upgrade-install (<module 'cloudinit.config.cc_package_update_upgrade_install' from '/usr/lib/python3/dist-packages/cloudinit/config/cc_package_update_upgrade_install.py'>) with frequency once-per-instance
2020-06-18 06:40:21,291 - handlers.py[DEBUG]: start: modules-final/config-package-update-upgrade-install: running config-package-update-upgrade-install with frequency once-per-instance
2020-06-18 06:40:21,291 - util.py[DEBUG]: Writing to /var/lib/cloud/instances/i-0c2ccc2ca413bce53/sem/config_package_update_upgrade_install - wb: [644] 24 bytes
2020-06-18 06:40:21,292 - helpers.py[DEBUG]: Running config-package-update-upgrade-install using lock (<FileLock using file '/var/lib/cloud/instances/i-0c2ccc2ca413bce53/sem/config_package_update_upgrade_install'>)
2020-06-18 06:40:21,292 - handlers.py[DEBUG]: finish: modules-final/config-package-update-upgrade-install: SUCCESS: config-package-update-upgrade-install ran successfully
2020-06-18 06:40:21,292 - stages.py[DEBUG]: Running module fan (<module 'cloudinit.config.cc_fan' from '/usr/lib/python3/dist-packages/cloudinit/config/cc_fan.py'>) with frequency once-per-instance
2020-06-18 06:40:21,292 - handlers.py[DEBUG]: start: modules-final/config-fan: running config-fan with frequency once-per-instance
2020-06-18 06:40:21,292 - util.py[DEBUG]: Writing to /var/lib/cloud/instances/i-0c2ccc2ca413bce53/sem/config_fan - wb: [644] 25 bytes
2020-06-18 06:40:21,292 - helpers.py[DEBUG]: Running config-fan using lock (<FileLock using file '/var/lib/cloud/instances/i-0c2ccc2ca413bce53/sem/config_fan'>)
2020-06-18 06:40:21,293 - cc_fan.py[DEBUG]: fan: no 'fan' config entry. disabling
2020-06-18 06:40:21,293 - handlers.py[DEBUG]: finish: modules-final/config-fan: SUCCESS: config-fan ran successfully
2020-06-18 06:40:21,293 - stages.py[DEBUG]: Running module landscape (<module 'cloudinit.config.cc_landscape' from '/usr/lib/python3/dist-packages/cloudinit/config/cc_landscape.py'>) with frequency once-per-instance
2020-06-18 06:40:21,293 - handlers.py[DEBUG]: start: modules-final/config-landscape: running config-landscape with frequency once-per-instance
2020-06-18 06:40:21,293 - util.py[DEBUG]: Writing to /var/lib/cloud/instances/i-0c2ccc2ca413bce53/sem/config_landscape - wb: [644] 24 bytes
2020-06-18 06:40:21,293 - helpers.py[DEBUG]: Running config-landscape using lock (<FileLock using file '/var/lib/cloud/instances/i-0c2ccc2ca413bce53/sem/config_landscape'>)
2020-06-18 06:40:21,293 - handlers.py[DEBUG]: finish: modules-final/config-landscape: SUCCESS: config-landscape ran successfully
2020-06-18 06:40:21,293 - stages.py[DEBUG]: Running module lxd (<module 'cloudinit.config.cc_lxd' from '/usr/lib/python3/dist-packages/cloudinit/config/cc_lxd.py'>) with frequency once-per-instance
2020-06-18 06:40:21,294 - handlers.py[DEBUG]: start: modules-final/config-lxd: running config-lxd with frequency once-per-instance
2020-06-18 06:40:21,294 - util.py[DEBUG]: Writing to /var/lib/cloud/instances/i-0c2ccc2ca413bce53/sem/config_lxd - wb: [644] 25 bytes
2020-06-18 06:40:21,294 - helpers.py[DEBUG]: Running config-lxd using lock (<FileLock using file '/var/lib/cloud/instances/i-0c2ccc2ca413bce53/sem/config_lxd'>)
2020-06-18 06:40:21,294 - cc_lxd.py[DEBUG]: Skipping module named lxd, not present or disabled by cfg
2020-06-18 06:40:21,294 - handlers.py[DEBUG]: finish: modules-final/config-lxd: SUCCESS: config-lxd ran successfully
2020-06-18 06:40:21,294 - stages.py[DEBUG]: Running module puppet (<module 'cloudinit.config.cc_puppet' from '/usr/lib/python3/dist-packages/cloudinit/config/cc_puppet.py'>) with frequency once-per-instance
2020-06-18 06:40:21,294 - handlers.py[DEBUG]: start: modules-final/config-puppet: running config-puppet with frequency once-per-instance
2020-06-18 06:40:21,295 - util.py[DEBUG]: Writing to /var/lib/cloud/instances/i-0c2ccc2ca413bce53/sem/config_puppet - wb: [644] 25 bytes
2020-06-18 06:40:21,295 - helpers.py[DEBUG]: Running config-puppet using lock (<FileLock using file '/var/lib/cloud/instances/i-0c2ccc2ca413bce53/sem/config_puppet'>)
2020-06-18 06:40:21,295 - cc_puppet.py[DEBUG]: Skipping module named puppet, no 'puppet' configuration found
2020-06-18 06:40:21,295 - handlers.py[DEBUG]: finish: modules-final/config-puppet: SUCCESS: config-puppet ran successfully
2020-06-18 06:40:21,295 - stages.py[DEBUG]: Running module chef (<module 'cloudinit.config.cc_chef' from '/usr/lib/python3/dist-packages/cloudinit/config/cc_chef.py'>) with frequency once-per-instance
2020-06-18 06:40:21,295 - handlers.py[DEBUG]: start: modules-final/config-chef: running config-chef with frequency once-per-instance
2020-06-18 06:40:21,295 - util.py[DEBUG]: Writing to /var/lib/cloud/instances/i-0c2ccc2ca413bce53/sem/config_chef - wb: [644] 25 bytes
2020-06-18 06:40:21,296 - helpers.py[DEBUG]: Running config-chef using lock (<FileLock using file '/var/lib/cloud/instances/i-0c2ccc2ca413bce53/sem/config_chef'>)
2020-06-18 06:40:21,296 - cc_chef.py[DEBUG]: Skipping module named chef, no 'chef' key in configuration
2020-06-18 06:40:21,296 - handlers.py[DEBUG]: finish: modules-final/config-chef: SUCCESS: config-chef ran successfully
2020-06-18 06:40:21,296 - stages.py[DEBUG]: Running module mcollective (<module 'cloudinit.config.cc_mcollective' from '/usr/lib/python3/dist-packages/cloudinit/config/cc_mcollective.py'>) with frequency once-per-instance
2020-06-18 06:40:21,296 - handlers.py[DEBUG]: start: modules-final/config-mcollective: running config-mcollective with frequency once-per-instance
2020-06-18 06:40:21,296 - util.py[DEBUG]: Writing to /var/lib/cloud/instances/i-0c2ccc2ca413bce53/sem/config_mcollective - wb: [644] 25 bytes
2020-06-18 06:40:21,297 - helpers.py[DEBUG]: Running config-mcollective using lock (<FileLock using file '/var/lib/cloud/instances/i-0c2ccc2ca413bce53/sem/config_mcollective'>)
2020-06-18 06:40:21,297 - cc_mcollective.py[DEBUG]: Skipping module named mcollective, no 'mcollective' key in configuration
2020-06-18 06:40:21,297 - handlers.py[DEBUG]: finish: modules-final/config-mcollective: SUCCESS: config-mcollective ran successfully
2020-06-18 06:40:21,297 - stages.py[DEBUG]: Running module salt-minion (<module 'cloudinit.config.cc_salt_minion' from '/usr/lib/python3/dist-packages/cloudinit/config/cc_salt_minion.py'>) with frequency once-per-instance
2020-06-18 06:40:21,297 - handlers.py[DEBUG]: start: modules-final/config-salt-minion: running config-salt-minion with frequency once-per-instance
2020-06-18 06:40:21,297 - util.py[DEBUG]: Writing to /var/lib/cloud/instances/i-0c2ccc2ca413bce53/sem/config_salt_minion - wb: [644] 25 bytes
2020-06-18 06:40:21,297 - helpers.py[DEBUG]: Running config-salt-minion using lock (<FileLock using file '/var/lib/cloud/instances/i-0c2ccc2ca413bce53/sem/config_salt_minion'>)
2020-06-18 06:40:21,297 - cc_salt_minion.py[DEBUG]: Skipping module named salt-minion, no 'salt_minion' key in configuration
2020-06-18 06:40:21,298 - handlers.py[DEBUG]: finish: modules-final/config-salt-minion: SUCCESS: config-salt-minion ran successfully
2020-06-18 06:40:21,298 - stages.py[DEBUG]: Running module rightscale_userdata (<module 'cloudinit.config.cc_rightscale_userdata' from '/usr/lib/python3/dist-packages/cloudinit/config/cc_rightscale_userdata.py'>) with frequency once-per-instance
2020-06-18 06:40:21,298 - handlers.py[DEBUG]: start: modules-final/config-rightscale_userdata: running config-rightscale_userdata with frequency once-per-instance
2020-06-18 06:40:21,298 - util.py[DEBUG]: Writing to /var/lib/cloud/instances/i-0c2ccc2ca413bce53/sem/config_rightscale_userdata - wb: [644] 25 bytes
2020-06-18 06:40:21,298 - helpers.py[DEBUG]: Running config-rightscale_userdata using lock (<FileLock using file '/var/lib/cloud/instances/i-0c2ccc2ca413bce53/sem/config_rightscale_userdata'>)
2020-06-18 06:40:21,298 - cc_rightscale_userdata.py[DEBUG]: Failed to get raw userdata in module rightscale_userdata
2020-06-18 06:40:21,298 - handlers.py[DEBUG]: finish: modules-final/config-rightscale_userdata: SUCCESS: config-rightscale_userdata ran successfully
2020-06-18 06:40:21,298 - stages.py[DEBUG]: Running module scripts-vendor (<module 'cloudinit.config.cc_scripts_vendor' from '/usr/lib/python3/dist-packages/cloudinit/config/cc_scripts_vendor.py'>) with frequency once-per-instance
2020-06-18 06:40:21,299 - handlers.py[DEBUG]: start: modules-final/config-scripts-vendor: running config-scripts-vendor with frequency once-per-instance
2020-06-18 06:40:21,299 - util.py[DEBUG]: Writing to /var/lib/cloud/instances/i-0c2ccc2ca413bce53/sem/config_scripts_vendor - wb: [644] 25 bytes
2020-06-18 06:40:21,299 - helpers.py[DEBUG]: Running config-scripts-vendor using lock (<FileLock using file '/var/lib/cloud/instances/i-0c2ccc2ca413bce53/sem/config_scripts_vendor'>)
2020-06-18 06:40:21,299 - handlers.py[DEBUG]: finish: modules-final/config-scripts-vendor: SUCCESS: config-scripts-vendor ran successfully
2020-06-18 06:40:21,299 - stages.py[DEBUG]: Running module scripts-per-once (<module 'cloudinit.config.cc_scripts_per_once' from '/usr/lib/python3/dist-packages/cloudinit/config/cc_scripts_per_once.py'>) with frequency once
2020-06-18 06:40:21,299 - handlers.py[DEBUG]: start: modules-final/config-scripts-per-once: running config-scripts-per-once with frequency once
2020-06-18 06:40:21,300 - util.py[DEBUG]: Writing to /var/lib/cloud/sem/config_scripts_per_once.once - wb: [644] 25 bytes
2020-06-18 06:40:21,300 - helpers.py[DEBUG]: Running config-scripts-per-once using lock (<FileLock using file '/var/lib/cloud/sem/config_scripts_per_once.once'>)
2020-06-18 06:40:21,300 - handlers.py[DEBUG]: finish: modules-final/config-scripts-per-once: SUCCESS: config-scripts-per-once ran successfully
2020-06-18 06:40:21,300 - stages.py[DEBUG]: Running module scripts-per-boot (<module 'cloudinit.config.cc_scripts_per_boot' from '/usr/lib/python3/dist-packages/cloudinit/config/cc_scripts_per_boot.py'>) with frequency always
2020-06-18 06:40:21,300 - handlers.py[DEBUG]: start: modules-final/config-scripts-per-boot: running config-scripts-per-boot with frequency always
2020-06-18 06:40:21,300 - helpers.py[DEBUG]: Running config-scripts-per-boot using lock (<cloudinit.helpers.DummyLock object at 0x7f3680775ac8>)
2020-06-18 06:40:21,300 - handlers.py[DEBUG]: finish: modules-final/config-scripts-per-boot: SUCCESS: config-scripts-per-boot ran successfully
2020-06-18 06:40:21,301 - stages.py[DEBUG]: Running module scripts-per-instance (<module 'cloudinit.config.cc_scripts_per_instance' from '/usr/lib/python3/dist-packages/cloudinit/config/cc_scripts_per_instance.py'>) with frequency once-per-instance
2020-06-18 06:40:21,301 - handlers.py[DEBUG]: start: modules-final/config-scripts-per-instance: running config-scripts-per-instance with frequency once-per-instance
2020-06-18 06:40:21,301 - util.py[DEBUG]: Writing to /var/lib/cloud/instances/i-0c2ccc2ca413bce53/sem/config_scripts_per_instance - wb: [644] 25 bytes
2020-06-18 06:40:21,301 - helpers.py[DEBUG]: Running config-scripts-per-instance using lock (<FileLock using file '/var/lib/cloud/instances/i-0c2ccc2ca413bce53/sem/config_scripts_per_instance'>)
2020-06-18 06:40:21,301 - handlers.py[DEBUG]: finish: modules-final/config-scripts-per-instance: SUCCESS: config-scripts-per-instance ran successfully
2020-06-18 06:40:21,301 - stages.py[DEBUG]: Running module scripts-user (<module 'cloudinit.config.cc_scripts_user' from '/usr/lib/python3/dist-packages/cloudinit/config/cc_scripts_user.py'>) with frequency once-per-instance
2020-06-18 06:40:21,302 - handlers.py[DEBUG]: start: modules-final/config-scripts-user: running config-scripts-user with frequency once-per-instance
2020-06-18 06:40:21,302 - util.py[DEBUG]: Writing to /var/lib/cloud/instances/i-0c2ccc2ca413bce53/sem/config_scripts_user - wb: [644] 24 bytes
2020-06-18 06:40:21,302 - helpers.py[DEBUG]: Running config-scripts-user using lock (<FileLock using file '/var/lib/cloud/instances/i-0c2ccc2ca413bce53/sem/config_scripts_user'>)
2020-06-18 06:40:21,302 - util.py[DEBUG]: Running command ['/var/lib/cloud/instance/scripts/part-001'] with allowed return codes [0] (shell=False, capture=False)
2020-06-18 06:47:13,277 - util.py[WARNING]: Failed running /var/lib/cloud/instance/scripts/part-001 [1]
2020-06-18 06:47:13,288 - util.py[DEBUG]: Failed running /var/lib/cloud/instance/scripts/part-001 [1]
Traceback (most recent call last):
  File "/usr/lib/python3/dist-packages/cloudinit/util.py", line 870, in runparts
    subp(prefix + [exe_path], capture=False)
  File "/usr/lib/python3/dist-packages/cloudinit/util.py", line 2065, in subp
    cmd=args)
cloudinit.util.ProcessExecutionError: Unexpected error while running command.
Command: ['/var/lib/cloud/instance/scripts/part-001']
Exit code: 1
Reason: -
Stdout: -
Stderr: -
2020-06-18 06:47:13,306 - cc_scripts_user.py[WARNING]: Failed to run module scripts-user (scripts in /var/lib/cloud/instance/scripts)
2020-06-18 06:47:13,307 - handlers.py[DEBUG]: finish: modules-final/config-scripts-user: FAIL: running config-scripts-user with frequency once-per-instance
2020-06-18 06:47:13,307 - util.py[WARNING]: Running module scripts-user (<module 'cloudinit.config.cc_scripts_user' from '/usr/lib/python3/dist-packages/cloudinit/config/cc_scripts_user.py'>) failed
2020-06-18 06:47:13,307 - util.py[DEBUG]: Running module scripts-user (<module 'cloudinit.config.cc_scripts_user' from '/usr/lib/python3/dist-packages/cloudinit/config/cc_scripts_user.py'>) failed
Traceback (most recent call last):
  File "/usr/lib/python3/dist-packages/cloudinit/stages.py", line 812, in _run_modules
    freq=freq)
  File "/usr/lib/python3/dist-packages/cloudinit/cloud.py", line 54, in run
    return self._runners.run(name, functor, args, freq, clear_on_fail)
  File "/usr/lib/python3/dist-packages/cloudinit/helpers.py", line 187, in run
    results = functor(*args)
  File "/usr/lib/python3/dist-packages/cloudinit/config/cc_scripts_user.py", line 45, in handle
    util.runparts(runparts_path)
  File "/usr/lib/python3/dist-packages/cloudinit/util.py", line 877, in runparts
    % (len(failed), len(attempted)))
RuntimeError: Runparts: 1 failures in 1 attempted commands
2020-06-18 06:47:13,310 - stages.py[DEBUG]: Running module ssh-authkey-fingerprints (<module 'cloudinit.config.cc_ssh_authkey_fingerprints' from '/usr/lib/python3/dist-packages/cloudinit/config/cc_ssh_authkey_fingerprints.py'>) with frequency once-per-instance
2020-06-18 06:47:13,311 - handlers.py[DEBUG]: start: modules-final/config-ssh-authkey-fingerprints: running config-ssh-authkey-fingerprints with frequency once-per-instance
2020-06-18 06:47:13,313 - util.py[DEBUG]: Writing to /var/lib/cloud/instances/i-0c2ccc2ca413bce53/sem/config_ssh_authkey_fingerprints - wb: [644] 25 bytes
2020-06-18 06:47:13,325 - helpers.py[DEBUG]: Running config-ssh-authkey-fingerprints using lock (<FileLock using file '/var/lib/cloud/instances/i-0c2ccc2ca413bce53/sem/config_ssh_authkey_fingerprints'>)
2020-06-18 06:47:13,330 - util.py[DEBUG]: Reading from /etc/ssh/sshd_config (quiet=False)
2020-06-18 06:47:13,331 - util.py[DEBUG]: Read 3262 bytes from /etc/ssh/sshd_config
2020-06-18 06:47:13,332 - util.py[DEBUG]: Reading from /home/ubuntu/.ssh/authorized_keys (quiet=False)
2020-06-18 06:47:13,333 - util.py[DEBUG]: Read 394 bytes from /home/ubuntu/.ssh/authorized_keys
2020-06-18 06:47:13,406 - handlers.py[DEBUG]: finish: modules-final/config-ssh-authkey-fingerprints: SUCCESS: config-ssh-authkey-fingerprints ran successfully
2020-06-18 06:47:13,407 - stages.py[DEBUG]: Running module keys-to-console (<module 'cloudinit.config.cc_keys_to_console' from '/usr/lib/python3/dist-packages/cloudinit/config/cc_keys_to_console.py'>) with frequency once-per-instance
2020-06-18 06:47:13,407 - handlers.py[DEBUG]: start: modules-final/config-keys-to-console: running config-keys-to-console with frequency once-per-instance
2020-06-18 06:47:13,407 - util.py[DEBUG]: Writing to /var/lib/cloud/instances/i-0c2ccc2ca413bce53/sem/config_keys_to_console - wb: [644] 25 bytes
2020-06-18 06:47:13,407 - helpers.py[DEBUG]: Running config-keys-to-console using lock (<FileLock using file '/var/lib/cloud/instances/i-0c2ccc2ca413bce53/sem/config_keys_to_console'>)
2020-06-18 06:47:13,411 - util.py[DEBUG]: Running command ['/usr/lib/cloud-init/write-ssh-key-fingerprints', '', 'ssh-dss'] with allowed return codes [0] (shell=False, capture=True)
2020-06-18 06:47:13,557 - handlers.py[DEBUG]: finish: modules-final/config-keys-to-console: SUCCESS: config-keys-to-console ran successfully
2020-06-18 06:47:13,557 - stages.py[DEBUG]: Running module phone-home (<module 'cloudinit.config.cc_phone_home' from '/usr/lib/python3/dist-packages/cloudinit/config/cc_phone_home.py'>) with frequency once-per-instance
2020-06-18 06:47:13,558 - handlers.py[DEBUG]: start: modules-final/config-phone-home: running config-phone-home with frequency once-per-instance
2020-06-18 06:47:13,558 - util.py[DEBUG]: Writing to /var/lib/cloud/instances/i-0c2ccc2ca413bce53/sem/config_phone_home - wb: [644] 25 bytes
2020-06-18 06:47:13,559 - helpers.py[DEBUG]: Running config-phone-home using lock (<FileLock using file '/var/lib/cloud/instances/i-0c2ccc2ca413bce53/sem/config_phone_home'>)
2020-06-18 06:47:13,559 - cc_phone_home.py[DEBUG]: Skipping module named phone-home, no 'phone_home' configuration found
2020-06-18 06:47:13,559 - handlers.py[DEBUG]: finish: modules-final/config-phone-home: SUCCESS: config-phone-home ran successfully
2020-06-18 06:47:13,559 - stages.py[DEBUG]: Running module final-message (<module 'cloudinit.config.cc_final_message' from '/usr/lib/python3/dist-packages/cloudinit/config/cc_final_message.py'>) with frequency always
2020-06-18 06:47:13,559 - handlers.py[DEBUG]: start: modules-final/config-final-message: running config-final-message with frequency always
2020-06-18 06:47:13,559 - helpers.py[DEBUG]: Running config-final-message using lock (<cloudinit.helpers.DummyLock object at 0x7f3684cd2048>)
2020-06-18 06:47:13,559 - util.py[DEBUG]: Reading from /proc/uptime (quiet=False)
2020-06-18 06:47:13,559 - util.py[DEBUG]: Read 13 bytes from /proc/uptime
2020-06-18 06:47:13,565 - util.py[DEBUG]: Cloud-init v. 18.5-45-g3554ffe8-0ubuntu1~18.04.1 finished at Thu, 18 Jun 2020 06:47:13 +0000. Datasource DataSourceEc2Local.  Up 439.87 seconds
2020-06-18 06:47:13,565 - util.py[DEBUG]: Writing to /var/lib/cloud/instance/boot-finished - wb: [644] 81 bytes
2020-06-18 06:47:13,565 - handlers.py[DEBUG]: finish: modules-final/config-final-message: SUCCESS: config-final-message ran successfully
2020-06-18 06:47:13,565 - stages.py[DEBUG]: Running module power-state-change (<module 'cloudinit.config.cc_power_state_change' from '/usr/lib/python3/dist-packages/cloudinit/config/cc_power_state_change.py'>) with frequency once-per-instance
2020-06-18 06:47:13,565 - handlers.py[DEBUG]: start: modules-final/config-power-state-change: running config-power-state-change with frequency once-per-instance
2020-06-18 06:47:13,565 - util.py[DEBUG]: Writing to /var/lib/cloud/instances/i-0c2ccc2ca413bce53/sem/config_power_state_change - wb: [644] 25 bytes
2020-06-18 06:47:13,566 - helpers.py[DEBUG]: Running config-power-state-change using lock (<FileLock using file '/var/lib/cloud/instances/i-0c2ccc2ca413bce53/sem/config_power_state_change'>)
2020-06-18 06:47:13,566 - cc_power_state_change.py[DEBUG]: no power_state provided. doing nothing
2020-06-18 06:47:13,566 - handlers.py[DEBUG]: finish: modules-final/config-power-state-change: SUCCESS: config-power-state-change ran successfully
2020-06-18 06:47:13,566 - main.py[DEBUG]: Ran 20 modules with 1 failures
2020-06-18 06:47:13,568 - util.py[DEBUG]: Creating symbolic link from '/run/cloud-init/result.json' => '../../var/lib/cloud/data/result.json'
2020-06-18 06:47:13,568 - util.py[DEBUG]: Reading from /proc/uptime (quiet=False)
2020-06-18 06:47:13,568 - util.py[DEBUG]: Read 13 bytes from /proc/uptime
2020-06-18 06:47:13,568 - util.py[DEBUG]: cloud-init mode 'modules' took 412.371 seconds (412.37)
2020-06-18 06:47:13,568 - handlers.py[DEBUG]: finish: modules-final: FAIL: running modules for final
